Workbook

Sheet OEE2
B2: # | C2: Turno | D2: Lineas consideradas | E2: Tiempo total de producción (hrs) | F2: Sin pedido (hrs) | G2: CYL Teórico (hrs) | H2: Mantenimiento Programado | I2: Tiempo disponible (hrs) | J2: CYL Excedido (hrs) | K2: Operación (hrs) | L2: Mecánicos (hrs) | M2: Otros (hrs) | N2: Reducción de ritmo (hrs) | O2: Micro paros (hrs) | P2: Sin clasificar (hrs) | Q2: Tiempo efectivo | R2: Capacidad Utilizada (%) | S2: Efectividad (%) | T2: Rendimiento (%) | U2: OEE1 (%) | V2: OEE2 (%) | W2: Producto teórico en masas | X2: Producto envuelto en masas | Y2: IPFM(%) | Z2: Tiempos perdidos (hr)
B3: 1 | D3: Pan bolleria | E3: 168 | F3: 104.27 | G3: 10.1 | H3: 0 | I3: 53.63 | J3: 1.54 | K3: 0.6 | L3: 0.55 | M3: 0.79 | N3: 1.56 | O3: 0.32 | P3: 0 | Q3: 48.27 | R3: 31.92 | S3: 90 | T3: 95.97 | U3: 27.57 | V3: 86.38 | W3: 157 | X3: 150.68 | Y3: =L3/I3*100 -> 1.0255454 | Z3: =IFERROR(SUM(J3:P3)," ") -> 5.36
B4: 2 | D4: Panqueleria | E4: 168 | F4: 126.59 | G4: 0 | H4: 0 | I4: 41.41 | J4: 0 | K4: 0 | L4: 0 | M4: 0 | N4: 0.06999 | O4: 0.14 | P4: 0 | Q4: 41.19 | R4: 24.64 | S4: 99.49 | T4: 98.16 | U4: 24.07 | V4: 97.67 | W4: 101 | X4: 99.14 | Y4: =L4/I4*100 -> 0 | Z4: =IFERROR(SUM(J4:P4)," ") -> 0.20999
B5: 3 | D5: Tortillas | E5: 168 | F5: 84.68 | G5: 0 | H5: 0 | I5: 83.32 | J5: 0 | K5: 0.06 | L5: 0 | M5: 0.18 | N5: 0.29 | O5: 0.08 | P5: 0 | Q5: 82.7 | R5: 49.59 | S5: 99.26 | T5: 97.58 | U5: 48.04 | V5: 96.86 | W5: 194 | X5: 189.31 | Y5: =L5/I5*100 -> 0 | Z5: =IFERROR(SUM(J5:P5)," ") -> 0.61
D6: Total | E6: 504 | F6: 315.53 | G6: 10.1 | H6: 0 | I6: 178.36 | J6: 1.54 | K6: 0.66 | L6: 0.55 | M6: 0.97 | N6: 1.92 | O6: 0.54 | P6: 0 | Q6: 172.18 | R6: 35.38 | S6: 96.53 | T6: 97.15 | U6: 33.19 | V6: 93.78 | W6: 452 | X6: 439.14 | Y6: =L6/I6*100 -> 0.3083651 | Z6: =IFERROR(SUM(J6:P6)," ") -> 6.18

Sheet R. DESPERDICIOS (2)
M1: 1. BAJAS NO RECUPERABLES 2. BAJAS PARA REPROCESO 3. SEGUNDA SELECCIÓN 15.BAJAS PARA DONATIVOS | O1: 4.RESIDUOS/BARREDURA 5.MATERIAS PRIMAS 6.PRUEBAS 7.ARRANQUE NUEVAS LINEAS 8. DESPERDICIO DE DISEÑO NO RECUPERABLE 9.RESIDUOS/BARREDURA PARA REPROCESO 10.PRUEBAS PARA REPROCESO 13.DONATIVOS | Q1: BAJAS + RESIDUOS (*NO SE CONSIDERA EL DESPERDICIO DE DISEÑO PARA REPROCESO) | S1: 2. BAJAS PARA REPROCESO 9.RESIDUOS/BARREDURA PARA REPROCESO 10.PRUEBAS PARA REPROCESO | U1: 1. BAJAS NO RECUPERABLES 4.RESIDUOS/BARREDURA 5.MATERIAS PRIMAS 6.PRUEBAS 8. DESPERDICIO DE DISEÑO NO RECUPERABLE | W1: 2. BAJAS PARA REPROCESO 3. SEGUNDA SELECCIÓN 9.RESIDUOS/BARREDURA PARA REPROCESO 10.PRUEBAS PARA REPROCESO 13.DONATIVOS 15.BAJAS PARA DONATIVOS
B2: Línea | C2: Código producto | D2: Descripción | E2: Uom | F2: Código Masa | G2: Nombre Masa | H2: Masas Elaboradas (Piezas) | I2: Pt Registrado (Piezas) | J2: PT Registrado (Paquetes) | K2: Peso paq (kg) | L2: Toneladas producidas (ton) | M2: Bajas / Desperdicio de Proceso (kg) | N2: % Bajas / Desperdicio de Proceso (BAJAS) | O2: Residuos (kg) | P2: % Residuos (BARREDURA) | Q2: Desperdicio Total (kg) | R2: % Desperdicio Total (TOTAL WASTE) | S2: Reproceso (kg) | T2: % Reproceso | U2: Desperdicio alimento (kg) | V2: % Desperdicio alimento (FOOD WASTE) | W2: Recuperación (kg) | X2: % Recuperación | AA2: PPM | AB2: Cupo Por Bandeja / Caja Primario | AC2: Piezas x Caja
B3: PAN BOLLERIA | C3: 0987 | D3: Pan Super Perro 1p 405g Bolsa BIM | F3: S944 | G3: MASA PAN SUPER PANCHO / PERRO | H3: 18182.16* | I3: 124524 | J3: 20754 | K3: 0.417 | L3: 8.65441 | M3: 91.5 | N3: 1.042 | O3: 35 | P3: 0.3985 | Q3: 126.5 | R3: 1.4406 | S3: 50.5 | T3: 0.5751 | U3: 76 | V3: 0.8705 | W3: 50.5 | X3: 0.5751 | AA3: =IF(AC3=1,(I3*AC3),(I3*AC3)) -> #N/A | AB3: #N/A | AC3: #N/A
B4: PAN BOLLERIA | C4: 23618 | D4: Pan Integral 1p 650g Bolsa BIM | F4: S947 | G4: MASA PAN INTEGRAL 650G BIM | H4: 777.50* | I4: 21336 | J4: 21336 | K4: 0.656 | L4: 13.99641 | M4: 60.36 | N4: 0.4292 | O4: 7 | P4: 0.0497 | Q4: 67.36 | R4: 0.4789 | S4: 13.5 | T4: 0.0959 | U4: 25 | V4: 0.1782 | W4: 42.36 | X4: 0.3012 | AA4: =IF(AC4=1,(I4*AC4),(I4*AC4)) -> #N/A | AB4: #N/A | AC4: #N/A
B5: PAN BOLLERIA | C5: 23901 | D5: Pan Vital Fruticereal 1p 500g Bolsa BIM | F5: S1541 | G5: MASA PAN 100% FRUTICEREAL | I5: 10049 | J5: 10049 | K5: 0.518 | L5: 5.20538 | M5: 16 | N5: 0.2992 | O5: 125 | P5: 2.338 | Q5: 141 | R5: 2.6372 | S5: 0 | T5: 0 | U5: 141 | V5: 2.6372 | W5: 0 | X5: 0 | AA5: =IF(AC5=1,(I5*AC5),(I5*AC5)) -> #N/A | AB5: #N/A | AC5: #N/A
B6: PAN BOLLERIA | C6: 23935 | D6: Duopack Super Perro 1p 810g Bolsa BIM | I6: 1824 | J6: 152 | K6: 0.834 | L6: 0.12676 | AA6: =IF(AC6=1,(I6*AC6),(I6*AC6)) -> #N/A | AB6: #N/A | AC6: #N/A
B7: PAN BOLLERIA | C7: 26405 | D7: Duopack Pan Integral 1p 1300g Bolsa BIM | I7: 756 | J7: 378 | K7: 1.312 | L7: 0.49593 | AA7: =IF(AC7=1,(I7*AC7),(I7*AC7)) -> #N/A | AB7: #N/A | AC7: #N/A
B8: PAN BOLLERIA | C8: 26474 | D8: Pan Leche 1p 550g Bolsa LAL | F8: S1550 | G8: MASA PAN BLANCO 550G | H8: 3571.60* | I8: 26537 | J8: 26537 | K8: 0.5625 | L8: 14.92706 | M8: 573.37 | N8: 3.6043 | O8: 407.5 | P8: 2.5616 | Q8: 980.87 | R8: 6.1659 | S8: 147 | T8: 0.924 | U8: 569.5 | V8: 3.675 | W8: 411.37 | X8: 2.5859 | AA8: =IF(AC8=1,(I8*AC8),(I8*AC8)) -> #N/A | AB8: #N/A | AC8: #N/A
B9: PAN BOLLERIA | C9: 26475 | D9: Pan Mantequilla 1p 550g Bolsa LAL | F9: S1552 | G9: MASA PAN MATEQUILLA 550G | H9: 8001.90 | I9: 31675 | J9: 31675 | K9: 0.5625 | L9: 17.81718 | M9: 723.06 | N9: 3.7728 | O9: 624.5 | P9: 3.2585 | Q9: 1347.56 | R9: 7.0314 | S9: 163 | T9: 0.8505 | U9: 756.5 | V9: 4.0729 | W9: 591.06 | X9: 3.0841 | AA9: =IF(AC9=1,(I9*AC9),(I9*AC9)) -> #N/A | AB9: #N/A | AC9: #N/A
B10: PAN BOLLERIA | C10: 27031 | D10: Dpack Pan Fruticereal 1p 1000g Bolsa BIM | I10: 700 | J10: 350 | K10: 1.036 | L10: 0.3626 | AA10: =IF(AC10=1,(I10*AC10),(I10*AC10)) -> #N/A | AB10: #N/A | AC10: #N/A
B11: PAN BOLLERIA | C11: 28632 | D11: Pan Mantequilla 1p 600g Bolsa BIM | F11: S1557 | G11: MASA PAN MANTEQUILLA 600G | I11: 14288 | J11: 14288 | K11: 0.6108 | L11: 8.72711 | M11: 232.44 | N11: 2.5614 | O11: 115 | P11: 1.2672 | Q11: 347.44 | R11: 3.8287 | S11: 97.5 | T11: 1.0744 | U11: 140 | V11: 1.5788 | W11: 207.44 | X11: 2.2859 | AA11: =IF(AC11=1,(I11*AC11),(I11*AC11)) -> #N/A | AB11: #N/A | AC11: #N/A
B12: PAN BOLLERIA | C12: 29076 | D12: Pan Super Perro 12p 4860g CJA BIM | E12: cg | F12: S944 | G12: MASA PAN SUPER PANCHO / PERRO | H12: 18182.16 | I12: 98280 | J12: 1365 | K12: 5.016 | L12: 6.84684 | M12: 8 | N12: 0.1167 | O12: 0 | P12: 0 | Q12: 8 | R12: 0.1167 | S12: 8 | T12: 0.1167 | U12: 0 | V12: 0 | W12: 8 | X12: 0.1167 | AA12: =IF(AC12=1,(I12*AC12),(I12*AC12)) -> #N/A | AB12: #N/A | AC12: #N/A
B13: PAN BOLLERIA | C13: 29434 | D13: Pan Super Hamburguesa 12p 4200g CJA BIM | E13: cg | F13: S1088 | G13: MASA HAMBURGUESA 5" -2- | I13: 97344 | J13: 2028 | K13: 4.404 | L13: 8.93131 | AA13: =IF(AC13=1,(I13*AC13),(I13*AC13)) -> #N/A | AB13: #N/A | AC13: #N/A
B14: PAN BOLLERIA | C14: 29580 | D14: Pan Artesano Blanco 1p 500g Bolsa BIM | F14: S946 | G14: MASA PAN ARTESANO 500G BIM | H14: 2035.80 | I14: 13716 | J14: 13716 | K14: 0.5086 | L14: 6.97595 | M14: 60.13 | N14: 0.8435 | O14: 93 | P14: 1.3045 | Q14: 153.13 | R14: 2.148 | S14: 0 | T14: 0 | U14: 145 | V14: 2.0362 | W14: 8.13 | X14: 0.1141 | AA14: =IF(AC14=1,(I14*AC14),(I14*AC14)) -> #N/A | AB14: #N/A | AC14: #N/A
B15: PAN BOLLERIA | C15: 39651 | D15: Duopack Pan Artesano 1p 1000g Bolsa BIM | I15: 1456 | J15: 728 | K15: 1.017 | L15: 0.74037 | AA15: =IF(AC15=1,(I15*AC15),(I15*AC15)) -> #N/A | AB15: #N/A | AC15: #N/A
B16: PAN BOLLERIA | C16: 41647 | D16: Pan Mantequilla 12p 6600g CJA LAL | E16: cg | F16: S1552 | G16: MASA PAN MATEQUILLA 550G | H16: 8001.90* | I16: 45864 | J16: 3822 | K16: 6.75 | L16: 25.7985 | AA16: =IF(AC16=1,(I16*AC16),(I16*AC16)) -> #N/A | AB16: #N/A | AC16: #N/A
B17: PAN BOLLERIA | C17: 41648 | D17: Pan Leche 12p 6600g CJA LAL | F17: S1550 | G17: MASA PAN BLANCO 550G | H17: 3571.60 | I17: 40320 | J17: 3360 | K17: 6.75 | L17: 22.68 | M17: 1.5 | N17: 0.0066 | O17: 0 | P17: 0 | Q17: 1.5 | R17: 0.0066 | S17: 0 | T17: 0 | U17: 1.5 | V17: 0.0066 | W17: 0 | X17: 0 | AA17: =IF(AC17=1,(I17*AC17),(I17*AC17)) -> #N/A | AB17: #N/A | AC17: #N/A
B18: PAN BOLLERIA | C18: 41649 | D18: Pan Integral 12p 6840g CJA LAL | F18: S1566 | G18: MASA PAN INTEGRAL 570G | H18: 1768.80* | I18: 25488 | J18: 2124 | K18: 6.984 | L18: 14.83401 | M18: 48 | N18: 0.3225 | O18: 0 | P18: 0 | Q18: 48 | R18: 0.3225 | S18: 19 | T18: 0.1276 | U18: 29 | V18: 0.1951 | W18: 19 | X18: 0.1276 | AA18: =IF(AC18=1,(I18*AC18),(I18*AC18)) -> #N/A | AB18: #N/A | AC18: #N/A
B19: PAN BOLLERIA | C19: 45530 | D19: Pan Artesano Blanco 8p 4000g CJA BIM | F19: S946 | G19: MASA PAN ARTESANO 500G BIM | H19: 2035.80* | I19: 23512 | J19: 2939 | K19: 4.0688 | L19: 11.9582 | AA19: =IF(AC19=1,(I19*AC19),(I19*AC19)) -> #N/A | AB19: #N/A | AC19: #N/A
B20: PAN BOLLERIA | C20: 45533 | D20: Vital Fruticereal 8p 4000g CJA BIM | I20: 8288 | J20: 1036 | K20: 4.144 | L20: 4.29318 | AA20: =IF(AC20=1,(I20*AC20),(I20*AC20)) -> #N/A | AB20: #N/A | AC20: #N/A
B21: PAN BOLLERIA | C21: 45541 | D21: Pan Mantequilla 10p 6000g CJA BIM | E21: cc | F21: S1557 | G21: MASA PAN MANTEQUILLA 600G | I21: 17850 | J21: 1785 | K21: 6.108 | L21: 10.90278 | AA21: =IF(AC21=1,(I21*AC21),(I21*AC21)) -> #N/A | AB21: #N/A | AC21: #N/A
B22: PAN BOLLERIA | C22: 48629 | D22: Hamburguesa 42in 1p 700g Bolsa BIM | F22: S1581 | G22: MASA HAMBURGUESA 4.5" BIM | I22: 18640 | J22: 1864 | K22: 0.7223 | L22: 1.34636 | M22: 20 | N22: 1.4509 | O22: 12 | P22: 0.8705 | Q22: 32 | R22: 2.3215 | S22: 6 | T22: 0.4352 | U22: 26 | V22: 1.8945 | W22: 6 | X22: 0.4352 | AA22: =IF(AC22=1,(I22*AC22),(I22*AC22)) -> #N/A | AB22: #N/A | AC22: #N/A
B23: PAN BOLLERIA | C23: 48630 | D23: Pan CR 42in 1p 830g Bolsa BIM | E23: EACH | F23: S1581 | G23: MASA HAMBURGUESA 4.5" BIM | I23: 76760 | J23: 7676 | K23: 0.852 | L23: 6.53995 | M23: 8.5 | N23: 0.1298 | O23: 0 | P23: 0 | Q23: 8.5 | R23: 0.1298 | S23: 4.5 | T23: 0.0687 | U23: 4 | V23: 0.0611 | W23: 4.5 | X23: 0.0687 | AA23: =IF(AC23=1,(I23*AC23),(I23*AC23)) -> #N/A | AB23: #N/A | AC23: #N/A
B24: PAN BOLLERIA | C24: 500490 | D24: Horneaditos Pan Blan 16p 7200g CJA NP | F24: S1574 | G24: MASA PAN BLANCO 450G | H24: 5552.00* | I24: 74944 | J24: 4684 | K24: 7.296 | L24: 34.17446 | M24: 94 | N24: 0.2719 | O24: 299 | P24: 0.8649 | Q24: 393 | R24: 1.1369 | S24: 137 | T24: 0.3963 | U24: 256 | V24: 0.7435 | W24: 137 | X24: 0.3963 | AA24: =IF(AC24=1,(I24*AC24),(I24*AC24)) -> #N/A | AB24: #N/A | AC24: #N/A
B25: PAN BOLLERIA | C25: 500493 | D25: Horneaditos Supe Perro 15p 5550g CJA NP | F25: S1579 | G25: MASA SUPER PERRO HORNEADITOS | H25: 19399.50* | I25: 246960 | J25: 2744 | K25: 5.745 | L25: 15.76428 | M25: 96.5 | N25: 0.6084 | O25: 0 | P25: 0 | Q25: 96.5 | R25: 0.6084 | S25: 25 | T25: 0.1576 | U25: 71.5 | V25: 0.4515 | W25: 25 | X25: 0.1576 | AA25: =IF(AC25=1,(I25*AC25),(I25*AC25)) -> #N/A | AB25: #N/A | AC25: #N/A
B26: PAN BOLLERIA | C26: 504672 | D26: Pan Spr Hamburgue Ajon 1p 525g Bolsa BIM | E26: EACH | F26: S1088 | G26: MASA HAMBURGUESA 5" -2- | I26: 46404 | J26: 7734 | K26: 0.535 | L26: 4.13769 | M26: 107 | N26: 2.5207 | O26: 0 | P26: 0 | Q26: 107 | R26: 2.5207 | S26: 0 | T26: 0 | U26: 107 | V26: 2.5207 | W26: 0 | X26: 0 | AA26: =IF(AC26=1,(I26*AC26),(I26*AC26)) -> #N/A | AB26: #N/A | AC26: #N/A
B27: PAN BOLLERIA | C27: 505377 | D27: Horneaditos PanIntegral 16p 7200g CJA NP | E27: cg | F27: S3556 | G27: MASA PAN INTEGRAL 450G HORNEADITOS | I27: 37456 | J27: 2341 | K27: 7.296 | L27: 17.07993 | M27: 70 | N27: 0.4081 | O27: 0 | P27: 0 | Q27: 70 | R27: 0.4081 | S27: 17 | T27: 0.0991 | U27: 53 | V27: 0.3093 | W27: 17 | X27: 0.0991 | AA27: =IF(AC27=1,(I27*AC27),(I27*AC27)) -> #N/A | AB27: #N/A | AC27: #N/A
B28: PAN BOLLERIA | C28: 505976 | D28: Pan Blanco 1p 450g BOLSA LAL | F28: S4582 | G28: MASA PAN BLANCO 450G LALO | H28: 1126.50 | I28: 40210 | J28: 40210 | K28: 0.46 | L28: 18.4966 | M28: 543.36 | N28: 2.8289 | O28: 167 | P28: 0.8694 | Q28: 710.36 | R28: 3.6984 | S28: 162.5 | T28: 0.846 | U28: 437 | V28: 2.308 | W28: 273.36 | X28: 1.4232 | AA28: =IF(AC28=1,(I28*AC28),(I28*AC28)) -> #N/A | AB28: #N/A | AC28: #N/A
B29: PAN BOLLERIA | C29: 506250 | D29: Pan Blanco PRO 1p 470g BOLSA BIM | F29: S962414 | G29: MASA PAN BLANCO LECHE 470G | H29: 5300.00* | I29: 38660 | J29: 38660 | K29: 0.4896 | L29: 18.93102 | M29: 173.82 | N29: 0.9091 | O29: 14 | P29: 0.0732 | Q29: 187.82 | R29: 0.9824 | S29: 33 | T29: 0.1726 | U29: 75.5 | V29: 0.3972 | W29: 112.32 | X29: 0.5875 | AA29: =IF(AC29=1,(I29*AC29),(I29*AC29)) -> #N/A | AB29: #N/A | AC29: #N/A
B30: PAN BOLLERIA | C30: 506251 | D30: Pan Blanco PRO 1p 600g BOLSA BIM | F30: S962605 | G30: MASA PAN BLANCO LECHE 600G | H30: 2542.80* | I30: 49878 | J30: 49878 | K30: 0.6235 | L30: 31.10242 | M30: 510.69 | N30: 1.6062 | O30: 181 | P30: 0.5692 | Q30: 691.69 | R30: 2.1755 | S30: 50 | T30: 0.1572 | U30: 401 | V30: 1.2728 | W30: 290.69 | X30: 0.9143 | AA30: =IF(AC30=1,(I30*AC30),(I30*AC30)) -> #N/A | AB30: #N/A | AC30: #N/A
B31: PAN BOLLERIA | C31: 506252 | D31: Pan Blanco PRO 1p 730g BOLSA BIM | F31: S962416 | G31: MASA PAN BLANCO LECHE 730G | H31: 694.96* | I31: 24528 | J31: 24528 | K31: 0.7447 | L31: 18.26624 | M31: 190.11 | N31: 1.0237 | O31: 114 | P31: 0.6138 | Q31: 304.11 | R31: 1.6376 | S31: 25 | T31: 0.1346 | U31: 225.5 | V31: 1.2194 | W31: 78.61 | X31: 0.4233 | AA31: =IF(AC31=1,(I31*AC31),(I31*AC31)) -> #N/A | AB31: #N/A | AC31: #N/A
B32: PAN BOLLERIA | C32: 5523 | D32: Pan Super Hamburguesa 1p 350g Bolsa BIM | F32: S1088 | G32: MASA HAMBURGUESA 5" -2- | I32: 33880 | J32: 8470 | K32: 0.361 | L32: 3.05767 | M32: 77 | N32: 2.2813 | O32: 240.5 | P32: 7.1255 | Q32: 317.5 | R32: 9.4069 | S32: 37 | T32: 1.0962 | U32: 280.5 | V32: 8.4028 | W32: 37 | X32: 1.0962 | AA32: =IF(AC32=1,(I32*AC32),(I32*AC32)) -> #N/A | AB32: #N/A | AC32: #N/A
B33: PAN BOLLERIA | C33: 7494 | D33: Pan Perro 1p 405g Bolsa BIM | F33: S944 | G33: MASA PAN SUPER PANCHO / PERRO | H33: 18182.16 | I33: 6318 | J33: 1053 | K33: 0.417 | L33: 0.4391 | M33: 0 | N33: 0 | O33: 11.5 | P33: 2.5521 | Q33: 11.5 | R33: 2.5521 | S33: 0 | T33: 0 | U33: 11.5 | V33: 2.5521 | W33: 0 | X33: 0 | AA33: =IF(AC33=1,(I33*AC33),(I33*AC33)) -> #N/A | AB33: #N/A | AC33: #N/A
B34: PAN BOLLERIA | C34: 9466 | D34: Pan Hamburguesa Har 5in 1p880g Bolsa BIM | F34: SU105691 | G34: MASA HAMBURGUESA HARINA 5 PULG BIM | H34: 4515.10* | I34: 96000 | J34: 9600 | K34: 0.903 | L34: 8.6688 | M34: 84.75 | N34: 0.9659 | O34: 21 | P34: 0.2393 | Q34: 105.75 | R34: 1.2052 | S34: 28.5 | T34: 0.3248 | U34: 61 | V34: 0.6987 | W34: 44.75 | X34: 0.51 | AA34: =IF(AC34=1,(I34*AC34),(I34*AC34)) -> #N/A | AB34: #N/A | AC34: #N/A
B35: PAN BOLLERIA | C35: 963582 | D35: Pan Blanco 10p 5800g CJA BIM | F35: S962599 | G35: MASA PAN BLANCO LECHE 580G | H35: 2619.00* | I35: 45630 | J35: 4563 | K35: 5.979 | L35: 27.28217 | M35: 169.5 | N35: 0.6157 | O35: 75 | P35: 0.2724 | Q35: 244.5 | R35: 0.8882 | S35: 44 | T35: 0.1598 | U35: 200.5 | V35: 0.7295 | W35: 44 | X35: 0.1598 | AA35: =IF(AC35=1,(I35*AC35),(I35*AC35)) -> #N/A | AB35: #N/A | AC35: #N/A
B36: PAN BOLLERIA | C36: 963603 | D36: Duopack Pan Blanco 2p 1200g BOLSA BIM | E36: BG | F36: S962605 | G36: MASA PAN BLANCO LECHE 600G | H36: 2542.80 | I36: 2280 | J36: 1140 | K36: 1.23 | L36: 1.4022 | AA36: =IF(AC36=1,(I36*AC36),(I36*AC36)) -> #N/A | AB36: #N/A | AC36: #N/A
B37: PAN BOLLERIA | C37: 963728 | D37: Pan Bln TT 1p 450g BOLSA LAL | F37: S4582 | G37: MASA PAN BLANCO 450G LALO | H37: 1126.50* | I37: 22590 | J37: 22590 | K37: 0.4794 | L37: 10.83122 | M37: 0 | N37: 0 | O37: 85 | P37: 0.7786 | Q37: 85 | R37: 0.7786 | S37: 0 | T37: 0 | U37: 85 | V37: 0.7786 | W37: 0 | X37: 0 | AA37: =IF(AC37=1,(I37*AC37),(I37*AC37)) -> #N/A | AB37: #N/A | AC37: #N/A
B38: PAN BOLLERIA | C38: 964010 | D38: Pan Blanco PRO 10p 4700g CJA BIM | E38: CG | F38: S962414 | G38: MASA PAN BLANCO LECHE 470G | H38: 5300.00 | I38: 2630 | J38: 263 | K38: 4.89 | L38: 1.28607 | AA38: =IF(AC38=1,(I38*AC38),(I38*AC38)) -> #N/A | AB38: #N/A | AC38: #N/A
B39: PAN BOLLERIA | C39: 9685 | D39: Pan Hamburguesa 5in 1p 880g Bolsa BIM | F39: S500 | G39: MASA HAMBURGUESA 5" | I39: 39160 | J39: 3916 | K39: 0.906 | L39: 3.54789 | M39: 34.5 | N39: 0.963 | O39: 0 | P39: 0 | Q39: 34.5 | R39: 0.963 | S39: 0 | T39: 0 | U39: 34.5 | V39: 0.963 | W39: 0 | X39: 0 | AA39: 0 | AB39: 0 | AC39: 0
B40: PAN BOLLERIA | C40: 39707 | D40: Pan Integral 1p 570g Bolsa LAL | M40: 25.07 | N40: 100 | O40: 0 | P40: 0 | Q40: 25.07 | R40: 100 | S40: 0 | T40: 0 | U40: 21 | V40: 100 | W40: 4.07 | X40: 16.2479 | AA40: 0 | AB40: 0 | AC40: 0
...

Sheet OEE2 (FORMULA)
B2: # | C2: Turno | D2: Lineas consideradas | E2: Tiempo total de producción (hrs) | F2: Sin pedido (hrs) | G2: CYL Teórico (hrs) | H2: Mantenimiento Programado | I2: Tiempo disponible (hrs) | J2: CYL Excedido (hrs) | K2: Operación (hrs) | L2: Mecánicos (hrs) | M2: Otros (hrs) | N2: Reducción de ritmo (hrs) | O2: Micro paros (hrs) | P2: Sin clasificar (hrs) | Q2: Tiempo efectivo | R2: Capacidad Utilizada (%) | S2: Efectividad (%) | T2: Rendimiento (%) | U2: OEE1 (%) | V2: OEE2 (%) | W2: Producto teórico en masas | X2: Producto envuelto en masas | Y2: IPFM(%) | Z2: Tiempos perdidos (hr)
B3: 1 | D3: ='OEE2'!D3 -> Pan bolleria | E3: ='OEE2'!E3 -> 168 | F3: ='OEE2'!F3 -> 104.27 | G3: ='OEE2'!G3 -> 10.1 | H3: ='OEE2'!H3 -> 0 | I3: =E3-F3-G3-H3 -> 53.63 | J3: ='OEE2'!J3 -> 1.54 | K3: ='OEE2'!K3 -> 0.6 | L3: ='OEE2'!L3 -> 0.55 | M3: ='OEE2'!M3 -> 0.79 | N3: ='OEE2'!N3 -> 1.56 | O3: ='OEE2'!O3 -> 0.32 | P3: 0 | Q3: =IFERROR(I3-(SUM(J3:P3))," ") -> 48.27 | R3: =IFERROR(I3/E3*100," ") -> 31.922619 | S3: =IFERROR(Q3/I3*100," ") -> 90.005594 | T3: =IFERROR(X3/W3*100," ") -> 95.974522 | U3: =IFERROR(((R3/100)*(S3/100)*(T3/100))*100," ") -> 27.575537 | V3: =IFERROR(((S3/100)*(T3/100))*100," ") -> 86.382439 | W3: ='OEE2'!W3 -> 157 | X3: ='OEE2'!X3 -> 150.68 | Y3: =IFERROR(L3/I3*100," ") -> 1.0255454 | Z3: =IFERROR(SUM(J3:P3)," ") -> 5.36
B4: 2 | D4: ='OEE2'!D4 -> Panqueleria | E4: ='OEE2'!E4 -> 168 | F4: ='OEE2'!F4 -> 126.59 | G4: ='OEE2'!G4 -> 0 | H4: ='OEE2'!H4 -> 0 | I4: =E4-F4-G4-H4 -> 41.41 | J4: ='OEE2'!J4 -> 0 | K4: ='OEE2'!K4 -> 0 | L4: ='OEE2'!L4 -> 0 | M4: ='OEE2'!M4 -> 0 | N4: ='OEE2'!N4 -> 0.06999 | O4: ='OEE2'!O4 -> 0.14 | P4: ='OEE2'!P4 -> 0 | Q4: =IFERROR(I4-(SUM(J4:P4))," ") -> 41.20001 | R4: =IFERROR(I4/E4*100," ") -> 24.64881 | S4: =IFERROR(Q4/I4*100," ") -> 99.4929 | T4: =IFERROR(X4/W4*100," ") -> 98.158416 | U4: =IFERROR(((R4/100)*(S4/100)*(T4/100))*100," ") -> 24.072189 | V4: =IFERROR(((S4/100)*(T4/100))*100," ") -> 97.660655 | W4: ='OEE2'!W4 -> 101 | X4: ='OEE2'!X4 -> 99.14 | Y4: =IFERROR(L4/I4*100," ") -> 0 | Z4: =IFERROR(SUM(J4:P4)," ") -> 0.20999
B5: 3 | D5: ='OEE2'!D5 -> Tortillas | E5: ='OEE2'!E5 -> 168 | F5: ='OEE2'!F5 -> 84.68 | G5: ='OEE2'!G5 -> 0 | H5: ='OEE2'!H5 -> 0 | I5: =E5-F5-G5-H5 -> 83.32 | J5: ='OEE2'!J5 -> 0 | K5: ='OEE2'!K5 -> 0.06 | L5: ='OEE2'!L5 -> 0 | M5: ='OEE2'!M5 -> 0.18 | N5: ='OEE2'!N5 -> 0.29 | O5: ='OEE2'!O5 -> 0.08 | P5: ='OEE2'!P5 -> 0 | Q5: =IFERROR(I5-(SUM(J5:P5))," ") -> 82.71 | R5: =IFERROR(I5/E5*100," ") -> 49.595238 | S5: =IFERROR(Q5/I5*100," ") -> 99.267883 | T5: =IFERROR(X5/W5*100," ") -> 97.582474 | U5: =IFERROR(((R5/100)*(S5/100)*(T5/100))*100," ") -> 48.041943 | V5: =IFERROR(((S5/100)*(T5/100))*100," ") -> 96.868056 | W5: ='OEE2'!W5 -> 194 | X5: ='OEE2'!X5 -> 189.31 | Y5: =IFERROR(L5/I5*100," ") -> 0 | Z5: =IFERROR(SUM(J5:P5)," ") -> 0.61
D6: Total | E6: ='OEE2'!E6 -> 504 | F6: ='OEE2'!F6 -> 315.53 | G6: ='OEE2'!G6 -> 10.1 | H6: ='OEE2'!H6 -> 0 | I6: =E6-F6-G6-H6 -> 178.37 | J6: ='OEE2'!J6 -> 1.54 | K6: ='OEE2'!K6 -> 0.66 | L6: ='OEE2'!L6 -> 0.55 | M6: ='OEE2'!M6 -> 0.97 | N6: ='OEE2'!N6 -> 1.92 | O6: ='OEE2'!O6 -> 0.54 | P6: 0 | Q6: =IFERROR(I6-(SUM(J6:P6))," ") -> 172.19 | R6: =IFERROR(I6/E6*100," ") -> 35.390873 | S6: =IFERROR(Q6/I6*100," ") -> 96.535292 | T6: =IFERROR(X6/W6*100," ") -> 97.154867 | U6: =IFERROR(((R6/100)*(S6/100)*(T6/100))*100," ") -> 33.192652 | V6: =IFERROR(((S6/100)*(T6/100))*100," ") -> 93.788735 | W6: ='OEE2'!W6 -> 452 | X6: ='OEE2'!X6 -> 439.14 | Y6: =IFERROR(L6/I6*100," ") -> 0.30834782 | Z6: =IFERROR(SUM(J6:P6)," ") -> 6.18
E8: =E6-'OEE2'!E6 -> 0 | F8: =F6-'OEE2'!F6 -> 0 | G8: =G6-'OEE2'!G6 -> 0 | H8: =H6-'OEE2'!H6 -> 0 | I8: =I6-'OEE2'!I6 -> 0.01 | J8: =J6-'OEE2'!J6 -> 0 | K8: =K6-'OEE2'!K6 -> 0 | L8: =L6-'OEE2'!L6 -> 0 | ... Z8: =Z6-'OEE2'!Z6 -> 0

Sheet PT
M1: 1. BAJAS NO RECUPERABLES 2. BAJAS PARA REPROCESO 3. SEGUNDA SELECCIÓN 15.BAJAS PARA DONATIVOS | O1: 4.RESIDUOS/BARREDURA 5.MATERIAS PRIMAS 6.PRUEBAS 7.ARRANQUE NUEVAS LINEAS 8. DESPERDICIO DE DISEÑO NO RECUPERABLE 9.RESIDUOS/BARREDURA PARA REPROCESO 10.PRUEBAS PARA REPROCESO 13.DONATIVOS | Q1: BAJAS + RESIDUOS (*NO SE CONSIDERA EL DESPERDICIO DE DISEÑO PARA REPROCESO) | S1: 2. BAJAS PARA REPROCESO 9.RESIDUOS/BARREDURA PARA REPROCESO 10.PRUEBAS PARA REPROCESO | U1: 1. BAJAS NO RECUPERABLES 4.RESIDUOS/BARREDURA 5.MATERIAS PRIMAS 6.PRUEBAS 8. DESPERDICIO DE DISEÑO NO RECUPERABLE | W1: 2. BAJAS PARA REPROCESO 3. SEGUNDA SELECCIÓN 9.RESIDUOS/BARREDURA PARA REPROCESO 10.PRUEBAS PARA REPROCESO 13.DONATIVOS 15.BAJAS PARA DONATIVOS
B2: Línea | C2: Código producto | D2: Descripción | E2: Uom | F2: Código Masa | G2: Nombre Masa | H2: Masas Elaboradas (Piezas) | I2: Pt Registrado (Piezas) | J2: PT Registrado (Paquetes) | K2: Peso paq (kg) | L2: Toneladas producidas (ton) | M2: Bajas / Desperdicio de Proceso (kg) | N2: % Bajas / Desperdicio de Proceso (BAJAS) | O2: Residuos (kg) | P2: % Residuos (BARREDURA) | Q2: Desperdicio Total (kg) | R2: % Desperdicio Total (TOTAL WASTE) | S2: Reproceso (kg) | T2: % Reproceso | U2: Desperdicio alimento (kg) | V2: % Desperdicio alimento (FOOD WASTE) | W2: Recuperación (kg) | X2: % Recuperación | AA2: PPM | AB2: Cupo Por Bandeja / Caja Primario | AC2: Piezas x Caja
B3: PAN BOLLERIA | C3: 987 | D3: Pan Super Perro 1p 405g Bolsa BIM | F3: S944 | G3: MASA PAN SUPER PANCHO / PERRO | H3: 29607 | I3: 11124 | J3: 1854 | K3: 0.418 | L3: 0.77497 | M3: 39 | N3: 4.7446 | O3: 8 | P3: 0.9732 | Q3: 47 | R3: 5.7179 | S3: 18 | T3: 2.1898 | U3: 29 | V3: 3.607 | W3: 18 | X3: 2.1898 | AA3: =IFERROR(IF(AC3=1,(I3*AC3),(I3*AC3)),0) -> 0 | AB3: =_xlfn.XLOOKUP($C:$C,'DT PPM'!$F:$F,'DT PPM'!$D:$D) -> #N/A | AC3: =VLOOKUP(C3,'DT PPM'!$C$3:$E$1048576,3,0) -> #N/A
B4: PAN BOLLERIA | C4: 23618 | D4: Pan Integral 1p 650g Bolsa BIM | E4: EACH | F4: S947 | G4: MASA PAN INTEGRAL 650G BIM | H4: 1565.80* | I4: 4392 | J4: 4392 | K4: 0.6666 | L4: 2.9277 | M4: 13 | N4: 0.442 | O4: 0 | P4: 0 | Q4: 13 | R4: 0.442 | S4: 13 | T4: 0.442 | U4: 0 | V4: 0 | W4: 13 | X4: 0.442 | AA4: =IFERROR(IF(AC4=1,(I4*AC4),(I4*AC4)),0) -> 0 | AB4: =_xlfn.XLOOKUP($C:$C,'DT PPM'!$F:$F,'DT PPM'!$D:$D) -> #N/A | AC4: =VLOOKUP(C4,'DT PPM'!$C$3:$E$1048576,3,0) -> #N/A
B5: PAN BOLLERIA | C5: 23901 | D5: Pan Vital Fruticereal 1p 500g Bolsa BIM | F5: S1541 | G5: MASA PAN 100% FRUTICEREAL | H5: 2450.2 | I5: 2717 | J5: 2717 | K5: 0.518 | L5: 1.4074 | M5: 24 | N5: 1.5524 | O5: 114.5 | P5: 7.4066 | Q5: 138.5 | R5: 8.9591 | S5: 0 | T5: 0 | U5: 138.5 | V5: 8.9591 | W5: 0 | X5: 0 | AA5: =IFERROR(IF(AC5=1,(I5*AC5),(I5*AC5)),0) -> 0 | AB5: =_xlfn.XLOOKUP($C:$C,'DT PPM'!$F:$F,'DT PPM'!$D:$D) -> #N/A | AC5: =VLOOKUP(C5,'DT PPM'!$C$3:$E$1048576,3,0) -> #N/A
B6: PAN BOLLERIA | C6: 26405 | D6: Duopack Pan Integral 1p 1300g Bolsa BIM | I6: 120 | J6: 60 | K6: 1.3331 | L6: 0.07998 | AA6: =IFERROR(IF(AC6=1,(I6*AC6),(I6*AC6)),0) -> 0 | AB6: =_xlfn.XLOOKUP($C:$C,'DT PPM'!$F:$F,'DT PPM'!$D:$D) -> #N/A | AC6: =VLOOKUP(C6,'DT PPM'!$C$3:$E$1048576,3,0) -> #N/A
B7: PAN BOLLERIA | C7: 26474 | D7: Pan Leche 1p 550g Bolsa LAL | F7: S1550 | G7: MASA PAN BLANCO 550G | H7: 7060.80* | I7: 2093 | J7: 2093 | K7: 0.5701 | L7: 1.19321 | M7: 43.56 | N7: 3.3826 | O7: 51 | P7: 3.9603 | Q7: 94.56 | R7: 7.3429 | S7: 90 | T7: 6.9888 | U7: 0 | V7: 0 | W7: 94.56 | X7: 7.3429 | AA7: =IFERROR(IF(AC7=1,(I7*AC7),(I7*AC7)),0) -> 0 | AB7: =_xlfn.XLOOKUP($C:$C,'DT PPM'!$F:$F,'DT PPM'!$D:$D) -> #N/A | AC7: =VLOOKUP(C7,'DT PPM'!$C$3:$E$1048576,3,0) -> #N/A
B8: PAN BOLLERIA | C8: 26475 | D8: Pan Mantequilla 1p 550g Bolsa LAL | F8: S1552 | G8: MASA PAN MATEQUILLA 550G | H8: 8788.00* | I8: 4417 | J8: 4417 | K8: 0.5701 | L8: 2.51813 | M8: 63.93 | N8: 2.3643 | O8: 122 | P8: 4.5117 | Q8: 185.93 | R8: 6.8761 | S8: 125 | T8: 4.6226 | U8: 33 | V8: 1.2935 | W8: 152.93 | X8: 5.6557 | AA8: =IFERROR(IF(AC8=1,(I8*AC8),(I8*AC8)),0) -> 0 | AB8: =_xlfn.XLOOKUP($C:$C,'DT PPM'!$F:$F,'DT PPM'!$D:$D) -> #N/A | AC8: =VLOOKUP(C8,'DT PPM'!$C$3:$E$1048576,3,0) -> #N/A
B9: PAN BOLLERIA | C9: 27031 | D9: Dpack Pan Fruticereal 1p 1000g Bolsa BIM | I9: 260 | J9: 130 | K9: 1.036 | L9: 0.13468 | AA9: =IFERROR(IF(AC9=1,(I9*AC9),(I9*AC9)),0) -> 0 | AB9: =_xlfn.XLOOKUP($C:$C,'DT PPM'!$F:$F,'DT PPM'!$D:$D) -> #N/A | AC9: =VLOOKUP(C9,'DT PPM'!$C$3:$E$1048576,3,0) -> #N/A
B10: PAN BOLLERIA | C10: 28632 | D10: Pan Mantequilla 1p 600g Bolsa BIM | F10: S1557 | G10: MASA PAN MANTEQUILLA 600G | H10: 823.5 | I10: 3448 | J10: 3448 | K10: 0.618 | L10: 2.13086 | M10: 21 | N10: 0.9758 | O10: 0 | P10: 0 | Q10: 21 | R10: 0.9758 | S10: 21 | T10: 0.9758 | U10: 0 | V10: 0 | W10: 21 | X10: 0.9758 | AA10: =IFERROR(IF(AC10=1,(I10*AC10),(I10*AC10)),0) -> 0 | AB10: =_xlfn.XLOOKUP($C:$C,'DT PPM'!$F:$F,'DT PPM'!$D:$D) -> #N/A | AC10: =VLOOKUP(C10,'DT PPM'!$C$3:$E$1048576,3,0) -> #N/A
B11: PAN BOLLERIA | C11: 29076 | D11: Pan Super Perro 12p 4860g CJA BIM | F11: S944 | G11: MASA PAN SUPER PANCHO / PERRO | H11: 29607 | I11: 10080 | J11: 140 | K11: 5.016 | L11: 0.70224 | AA11: =IFERROR(IF(AC11=1,(I11*AC11),(I11*AC11)),0) -> 0 | AB11: =_xlfn.XLOOKUP($C:$C,'DT PPM'!$F:$F,'DT PPM'!$D:$D) -> #N/A | AC11: =VLOOKUP(C11,'DT PPM'!$C$3:$E$1048576,3,0) -> #N/A
B12: PAN BOLLERIA | C12: 29434 | D12: Pan Super Hamburguesa 12p 4200g CJA BIM | E12: cg | F12: S1088 | G12: MASA HAMBURGUESA 5" -2- | H12: 3570.04 | I12: 11760 | J12: 245 | K12: 4.404 | L12: 1.07898 | AA12: =IFERROR(IF(AC12=1,(I12*AC12),(I12*AC12)),0) -> 0 | AB12: =_xlfn.XLOOKUP($C:$C,'DT PPM'!$F:$F,'DT PPM'!$D:$D) -> #N/A | AC12: =VLOOKUP(C12,'DT PPM'!$C$3:$E$1048576,3,0) -> #N/A
B13: PAN BOLLERIA | C13: 41647 | D13: Pan Mantequilla 12p 6600g CJA LAL | E13: cg | F13: S1552 | G13: MASA PAN MATEQUILLA 550G | H13: 8788 | I13: 10080 | J13: 840 | K13: 6.8414 | L13: 5.74677 | AA13: =IFERROR(IF(AC13=1,(I13*AC13),(I13*AC13)),0) -> 0 | AB13: =_xlfn.XLOOKUP($C:$C,'DT PPM'!$F:$F,'DT PPM'!$D:$D) -> #N/A | AC13: =VLOOKUP(C13,'DT PPM'!$C$3:$E$1048576,3,0) -> #N/A
B14: PAN BOLLERIA | C14: 41648 | D14: Pan Leche 12p 6600g CJA LAL | E14: cg | F14: S1550 | G14: MASA PAN BLANCO 550G | H14: 7060.8 | I14: 7980 | J14: 665 | K14: 6.8414 | L14: 4.54953 | AA14: =IFERROR(IF(AC14=1,(I14*AC14),(I14*AC14)),0) -> 0 | AB14: =_xlfn.XLOOKUP($C:$C,'DT PPM'!$F:$F,'DT PPM'!$D:$D) -> #N/A | AC14: =VLOOKUP(C14,'DT PPM'!$C$3:$E$1048576,3,0) -> #N/A
B15: PAN BOLLERIA | C15: 41649 | D15: Pan Integral 12p 6840g CJA LAL | F15: S1566 | G15: MASA PAN INTEGRAL 570G | H15: 3546.80* | I15: 4452 | J15: 371 | K15: 6.9697 | L15: 2.58575 | M15: 8 | N15: 0.3084 | O15: 0 | P15: 0 | Q15: 8 | R15: 0.3084 | S15: 8 | T15: 0.3084 | U15: 0 | V15: 0 | W15: 8 | X15: 0.3084 | AA15: =IFERROR(IF(AC15=1,(I15*AC15),(I15*AC15)),0) -> 0 | AB15: =_xlfn.XLOOKUP($C:$C,'DT PPM'!$F:$F,'DT PPM'!$D:$D) -> #N/A | AC15: =VLOOKUP(C15,'DT PPM'!$C$3:$E$1048576,3,0) -> #N/A
B16: PAN BOLLERIA | C16: 45533 | D16: Vital Fruticereal 8p 4000g CJA BIM | E16: CG | F16: S1541 | G16: MASA PAN 100% FRUTICEREAL | H16: 2450.20* | I16: 3376 | J16: 422 | K16: 4.144 | L16: 1.74876 | AA16: =IFERROR(IF(AC16=1,(I16*AC16),(I16*AC16)),0) -> 0 | AB16: =_xlfn.XLOOKUP($C:$C,'DT PPM'!$F:$F,'DT PPM'!$D:$D) -> #N/A | AC16: =VLOOKUP(C16,'DT PPM'!$C$3:$E$1048576,3,0) -> #N/A
B17: PAN BOLLERIA | C17: 45541 | D17: Pan Mantequilla 10p 6000g CJA BIM | E17: cc | F17: S1557 | G17: MASA PAN MANTEQUILLA 600G | H17: 823.50* | I17: 2800 | J17: 280 | K17: 6.1802 | L17: 1.73045 | AA17: =IFERROR(IF(AC17=1,(I17*AC17),(I17*AC17)),0) -> 0 | AB17: =_xlfn.XLOOKUP($C:$C,'DT PPM'!$F:$F,'DT PPM'!$D:$D) -> #N/A | AC17: =VLOOKUP(C17,'DT PPM'!$C$3:$E$1048576,3,0) -> #N/A
B18: PAN BOLLERIA | C18: 48629 | D18: Hamburguesa 42in 1p 700g Bolsa BIM | E18: EACH | F18: S1581 | G18: MASA HAMBURGUESA 4.5" BIM | H18: 4787 | I18: 2500 | J18: 250 | K18: 0.7223 | L18: 0.18057 | AA18: =IFERROR(IF(AC18=1,(I18*AC18),(I18*AC18)),0) -> 0 | AB18: =_xlfn.XLOOKUP($C:$C,'DT PPM'!$F:$F,'DT PPM'!$D:$D) -> #N/A | AC18: =VLOOKUP(C18,'DT PPM'!$C$3:$E$1048576,3,0) -> #N/A
B19: PAN BOLLERIA | C19: 48630 | D19: Pan CR 42in 1p 830g Bolsa BIM | E19: EACH | F19: S1581 | G19: MASA HAMBURGUESA 4.5" BIM | H19: 4787.00* | I19: 6260 | J19: 626 | K19: 0.852 | L19: 0.53335 | AA19: =IFERROR(IF(AC19=1,(I19*AC19),(I19*AC19)),0) -> 0 | AB19: =_xlfn.XLOOKUP($C:$C,'DT PPM'!$F:$F,'DT PPM'!$D:$D) -> #N/A | AC19: =VLOOKUP(C19,'DT PPM'!$C$3:$E$1048576,3,0) -> #N/A
B20: PAN BOLLERIA | C20: 500490 | D20: Horneaditos Pan Blan 16p 7200g CJA NP | F20: S1574 | G20: MASA PAN BLANCO 450G | H20: 9878.40* | I20: 18128 | J20: 1133 | K20: 7.3038 | L20: 8.2752 | M20: 37 | N20: 0.4428 | O20: 43 | P20: 0.5146 | Q20: 80 | R20: 0.9574 | S20: 37 | T20: 0.4428 | U20: 43 | V20: 0.5169 | W20: 37 | X20: 0.4428 | AA20: =IFERROR(IF(AC20=1,(I20*AC20),(I20*AC20)),0) -> 0 | AB20: =_xlfn.XLOOKUP($C:$C,'DT PPM'!$F:$F,'DT PPM'!$D:$D) -> #N/A | AC20: =VLOOKUP(C20,'DT PPM'!$C$3:$E$1048576,3,0) -> #N/A
B21: PAN BOLLERIA | C21: 500493 | D21: Horneaditos Supe Perro 15p 5550g CJA NP | E21: cg | F21: S1579 | G21: MASA SUPER PERRO HORNEADITOS | H21: 42525.00* | I21: 41760 | J21: 464 | K21: 5.989 | L21: 2.77891 | M21: 11 | N21: 0.3942 | O21: 0 | P21: 0 | Q21: 11 | R21: 0.3942 | S21: 11 | T21: 0.3942 | U21: 0 | V21: 0 | W21: 11 | X21: 0.3942 | AA21: =IFERROR(IF(AC21=1,(I21*AC21),(I21*AC21)),0) -> 0 | AB21: =_xlfn.XLOOKUP($C:$C,'DT PPM'!$F:$F,'DT PPM'!$D:$D) -> #N/A | AC21: =VLOOKUP(C21,'DT PPM'!$C$3:$E$1048576,3,0) -> #N/A
B22: PAN BOLLERIA | C22: 504672 | D22: Pan Spr Hamburgue Ajon 1p 525g Bolsa BIM | E22: EACH | F22: S1088 | G22: MASA HAMBURGUESA 5" -2- | H22: 3570.04* | I22: 7200 | J22: 1200 | K22: 0.535 | L22: 0.642 | AA22: =IFERROR(IF(AC22=1,(I22*AC22),(I22*AC22)),0) -> 0 | AB22: =_xlfn.XLOOKUP($C:$C,'DT PPM'!$F:$F,'DT PPM'!$D:$D) -> #N/A | AC22: =VLOOKUP(C22,'DT PPM'!$C$3:$E$1048576,3,0) -> #N/A
B23: PAN BOLLERIA | C23: 505377 | D23: Horneaditos PanIntegral 16p 7200g CJA NP | E23: cg | F23: S3556 | G23: MASA PAN INTEGRAL 450G HORNEADITOS | H23: 3499.20* | I23: 10320 | J23: 645 | K23: 7.3038 | L23: 4.71095 | M23: 31 | N23: 0.6496 | O23: 30 | P23: 0.6286 | Q23: 61 | R23: 1.2783 | S23: 31 | T23: 0.6496 | U23: 30 | V23: 0.6327 | W23: 31 | X23: 0.6496 | AA23: =IFERROR(IF(AC23=1,(I23*AC23),(I23*AC23)),0) -> 0 | AB23: =_xlfn.XLOOKUP($C:$C,'DT PPM'!$F:$F,'DT PPM'!$D:$D) -> #N/A | AC23: =VLOOKUP(C23,'DT PPM'!$C$3:$E$1048576,3,0) -> #N/A
B24: PAN BOLLERIA | C24: 505976 | D24: Pan Blanco 1p 450g BOLSA LAL | E24: EACH | F24: S4582 | G24: MASA PAN BLANCO 450G LALO | H24: 4524.80* | I24: 6830 | J24: 6830 | K24: 0.473 | L24: 3.23059 | M24: 112.48 | N24: 3.3648 | O24: 0 | P24: 0 | Q24: 112.48 | R24: 3.3648 | S24: 47 | T24: 1.4058 | U24: 39 | V24: 1.1928 | W24: 73.48 | X24: 2.1982 | AA24: =IFERROR(IF(AC24=1,(I24*AC24),(I24*AC24)),0) -> 0 | AB24: =_xlfn.XLOOKUP($C:$C,'DT PPM'!$F:$F,'DT PPM'!$D:$D) -> #N/A | AC24: =VLOOKUP(C24,'DT PPM'!$C$3:$E$1048576,3,0) -> #N/A
B25: PAN BOLLERIA | C25: 506250 | D25: Pan Blanco PRO 1p 470g BOLSA BIM | F25: S962414 | G25: MASA PAN BLANCO LECHE 470G | H25: 5291 | I25: 6830 | J25: 6830 | K25: 0.4818 | L25: 3.29069 | M25: 131.9 | N25: 3.8344 | O25: 17.5 | P25: 0.5087 | Q25: 149.4 | R25: 4.3431 | S25: 42 | T25: 1.2208 | U25: 78.5 | V25: 2.3299 | W25: 70.9 | X25: 2.0612 | AA25: =IFERROR(IF(AC25=1,(I25*AC25),(I25*AC25)),0) -> 0 | AB25: =_xlfn.XLOOKUP($C:$C,'DT PPM'!$F:$F,'DT PPM'!$D:$D) -> #N/A | AC25: =VLOOKUP(C25,'DT PPM'!$C$3:$E$1048576,3,0) -> #N/A
B26: PAN BOLLERIA | C26: 506251 | D26: Pan Blanco PRO 1p 600g BOLSA BIM | E26: EACH | F26: S962605 | G26: MASA PAN BLANCO LECHE 600G | H26: 2513.70* | I26: 7002 | J26: 7002 | K26: 0.6104 | L26: 4.27402 | M26: 20 | N26: 0.4645 | O26: 11 | P26: 0.2555 | Q26: 31 | R26: 0.72 | S26: 20 | T26: 0.4645 | U26: 11 | V26: 0.2567 | W26: 20 | X26: 0.4645 | AA26: =IFERROR(IF(AC26=1,(I26*AC26),(I26*AC26)),0) -> 0 | AB26: =_xlfn.XLOOKUP($C:$C,'DT PPM'!$F:$F,'DT PPM'!$D:$D) -> #N/A | AC26: =VLOOKUP(C26,'DT PPM'!$C$3:$E$1048576,3,0) -> #N/A
B27: PAN BOLLERIA | C27: 506252 | D27: Pan Blanco PRO 1p 730g BOLSA BIM | E27: EACH | F27: S962416 | G27: MASA PAN BLANCO LECHE 730G | H27: 2070.30* | I27: 4326 | J27: 4326 | K27: 0.7447 | L27: 3.22161 | M27: 24.97 | N27: 0.7693 | O27: 0 | P27: 0 | Q27: 24.97 | R27: 0.7693 | S27: 22 | T27: 0.6776 | U27: 0 | V27: 0 | W27: 24.97 | X27: 0.7693 | AA27: =IFERROR(IF(AC27=1,(I27*AC27),(I27*AC27)),0) -> 0 | AB27: =_xlfn.XLOOKUP($C:$C,'DT PPM'!$F:$F,'DT PPM'!$D:$D) -> #N/A | AC27: =VLOOKUP(C27,'DT PPM'!$C$3:$E$1048576,3,0) -> #N/A
B28: PAN BOLLERIA | C28: 5523 | D28: Pan Super Hamburguesa 1p 350g Bolsa BIM | E28: EACH | F28: S1088 | G28: MASA HAMBURGUESA 5" -2- | H28: 3570.04 | I28: 1880 | J28: 470 | K28: 0.361 | L28: 0.16967 | M28: 7 | N28: 3.4538 | O28: 26 | P28: 12.8287 | Q28: 33 | R28: 16.2826 | S28: 7 | T28: 3.4538 | U28: 26 | V28: 13.2876 | W28: 7 | X28: 3.4538 | AA28: =IFERROR(IF(AC28=1,(I28*AC28),(I28*AC28)),0) -> 0 | AB28: =_xlfn.XLOOKUP($C:$C,'DT PPM'!$F:$F,'DT PPM'!$D:$D) -> #N/A | AC28: =VLOOKUP(C28,'DT PPM'!$C$3:$E$1048576,3,0) -> #N/A
B29: PAN BOLLERIA | C29: 7494 | D29: Pan Perro 1p 405g Bolsa BIM | E29: BG | F29: S944 | G29: MASA PAN SUPER PANCHO / PERRO | H29: 29607.00* | I29: 5616 | J29: 936 | K29: 0.419 | L29: 0.39218 | AA29: =IFERROR(IF(AC29=1,(I29*AC29),(I29*AC29)),0) -> 0 | AB29: =_xlfn.XLOOKUP($C:$C,'DT PPM'!$F:$F,'DT PPM'!$D:$D) -> #N/A | AC29: =VLOOKUP(C29,'DT PPM'!$C$3:$E$1048576,3,0) -> #N/A
B30: PAN BOLLERIA | C30: 9466 | D30: Pan Hamburguesa Har 5in 1p880g Bolsa BIM | F30: SU105691 | G30: MASA HAMBURGUESA HARINA 5 PULG BIM | I30: 18360 | J30: 1836 | K30: 0.919 | L30: 1.68728 | M30: 4 | N30: 0.2353 | O30: 8 | P30: 0.4707 | Q30: 12 | R30: 0.7061 | S30: 4 | T30: 0.2353 | U30: 8 | V30: 0.4718 | W30: 4 | X30: 0.2353 | AA30: =IFERROR(IF(AC30=1,(I30*AC30),(I30*AC30)),0) -> 0 | AB30: =_xlfn.XLOOKUP($C:$C,'DT PPM'!$F:$F,'DT PPM'!$D:$D) -> #N/A | AC30: =VLOOKUP(C30,'DT PPM'!$C$3:$E$1048576,3,0) -> #N/A
B31: PAN BOLLERIA | C31: 963582 | D31: Pan Blanco 10p 5800g CJA BIM | F31: S962599 | G31: MASA PAN BLANCO LECHE 580G | H31: 3472.00* | I31: 9450 | J31: 945 | K31: 5.979 | L31: 5.65015 | M31: 11 | N31: 0.1943 | O31: 0 | P31: 0 | Q31: 11 | R31: 0.1943 | S31: 11 | T31: 0.1943 | U31: 0 | V31: 0 | W31: 11 | X31: 0.1943 | AA31: =IFERROR(IF(AC31=1,(I31*AC31),(I31*AC31)),0) -> 0 | AB31: =_xlfn.XLOOKUP($C:$C,'DT PPM'!$F:$F,'DT PPM'!$D:$D) -> #N/A | AC31: =VLOOKUP(C31,'DT PPM'!$C$3:$E$1048576,3,0) -> #N/A
B32: PAN BOLLERIA | C32: 963603 | D32: Duopack Pan Blanco 2p 1200g BOLSA BIM | E32: BG | F32: S962605 | G32: MASA PAN BLANCO LECHE 600G | H32: 2513.7 | I32: 320 | J32: 160 | K32: 1.2208 | L32: 0.19532 | AA32: =IFERROR(IF(AC32=1,(I32*AC32),(I32*AC32)),0) -> 0 | AB32: =_xlfn.XLOOKUP($C:$C,'DT PPM'!$F:$F,'DT PPM'!$D:$D) -> #N/A | AC32: =VLOOKUP(C32,'DT PPM'!$C$3:$E$1048576,3,0) -> #N/A
B33: PAN BOLLERIA | C33: 963728 | D33: Pan Bln TT 1p 450g BOLSA LAL | E33: EACH | F33: S4582 | G33: MASA PAN BLANCO 450G LALO | H33: 4524.8 | I33: 3040 | J33: 3040 | K33: 0.473 | L33: 1.43792 | AA33: =IFERROR(IF(AC33=1,(I33*AC33),(I33*AC33)),0) -> 0 | AB33: =_xlfn.XLOOKUP($C:$C,'DT PPM'!$F:$F,'DT PPM'!$D:$D) -> #N/A | AC33: =VLOOKUP(C33,'DT PPM'!$C$3:$E$1048576,3,0) -> #N/A
B34: PAN BOLLERIA | C34: 963824 | D34: Duo Pack Pan Artesano Blanco MM 2p | E34: EACH | F34: SU105902 | G34: MASA PAN BLANCO ARTESANAL 500G MASA MADRE | H34: 2988 | I34: 520 | J34: 260 | K34: 1 | L34: 0.26 | AA34: =IFERROR(IF(AC34=1,(I34*AC34),(I34*AC34)),0) -> 0 | AB34: =_xlfn.XLOOKUP($C:$C,'DT PPM'!$F:$F,'DT PPM'!$D:$D) -> #N/A | AC34: =VLOOKUP(C34,'DT PPM'!$C$3:$E$1048576,3,0) -> #N/A
B35: PAN BOLLERIA | C35: 963833 | D35: Pan Blanco Artes MM 1p 500g BOLSA BIM | E35: EACH | F35: SU105902 | G35: MASA PAN BLANCO ARTESANAL 500G MASA MADRE | H35: 2988 | I35: 3465 | J35: 3465 | K35: 0.5036 | L35: 1.74497 | M35: 25 | N35: 1.3691 | O35: 56 | P35: 3.0668 | Q35: 81 | R35: 4.4359 | S35: 0 | T35: 0 | U35: 81 | V35: 4.4359 | W35: 0 | X35: 0 | AA35: =IFERROR(IF(AC35=1,(I35*AC35),(I35*AC35)),0) -> 0 | AB35: =_xlfn.XLOOKUP($C:$C,'DT PPM'!$F:$F,'DT PPM'!$D:$D) -> #N/A | AC35: =VLOOKUP(C35,'DT PPM'!$C$3:$E$1048576,3,0) -> #N/A
B36: PAN BOLLERIA | C36: 963909 | D36: Pan Artesano Blanco MM 8p 4000g CJA BIM | E36: EACH | F36: SU105902 | G36: MASA PAN BLANCO ARTESANAL 500G MASA MADRE | H36: 2988.00* | I36: 5040 | J36: 630 | K36: 4.08 | L36: 2.5704 | AA36: =IFERROR(IF(AC36=1,(I36*AC36),(I36*AC36)),0) -> 0 | AB36: =_xlfn.XLOOKUP($C:$C,'DT PPM'!$F:$F,'DT PPM'!$D:$D) -> #N/A | AC36: =VLOOKUP(C36,'DT PPM'!$C$3:$E$1048576,3,0) -> #N/A
B37: PAN BOLLERIA | C37: 964010 | D37: Pan Blanco PRO 10p 4700g CJA BIM | E37: CG | F37: S962414 | G37: MASA PAN BLANCO LECHE 470G | H37: 5291.00* | I37: 580 | J37: 58 | K37: 4.8357 | L37: 0.28047 | AA37: =IFERROR(IF(AC37=1,(I37*AC37),(I37*AC37)),0) -> 0 | AB37: =_xlfn.XLOOKUP($C:$C,'DT PPM'!$F:$F,'DT PPM'!$D:$D) -> #N/A | AC37: =VLOOKUP(C37,'DT PPM'!$C$3:$E$1048576,3,0) -> #N/A
B38: PAN BOLLERIA | C38: 9685 | D38: Pan Hamburguesa 5in 1p 880g Bolsa BIM | E38: EACH | F38: S500 | G38: MASA HAMBURGUESA 5" | I38: 4080 | J38: 408 | K38: 0.91 | L38: 0.37128 | M38: 0 | N38: 0 | O38: 30 | P38: 7.476 | Q38: 30 | R38: 7.476 | S38: 0 | T38: 0 | U38: 30 | V38: 7.476 | W38: 0 | X38: 0 | AA38: =IFERROR(IF(AC38=1,(I38*AC38),(I38*AC38)),0) -> 0 | AB38: =_xlfn.XLOOKUP($C:$C,'DT PPM'!$F:$F,'DT PPM'!$D:$D) -> #N/A | AC38: =VLOOKUP(C38,'DT PPM'!$C$3:$E$1048576,3,0) -> #N/A
B39: PAN BOLLERIA | C39: 29580 | D39: Pan Artesano Blanco 1p 500g Bolsa BIM | M39: 8 | N39: 100 | O39: 0 | P39: 0 | Q39: 8 | R39: 100 | S39: 0 | T39: 0 | U39: 8 | V39: 100 | W39: 0 | X39: 0 | AA39: =IFERROR(IF(AC39=1,(I39*AC39),(I39*AC39)),0) -> 0 | AB39: =_xlfn.XLOOKUP($C:$C,'DT PPM'!$F:$F,'DT PPM'!$D:$D) -> #N/A | AC39: =VLOOKUP(C39,'DT PPM'!$C$3:$E$1048576,3,0) -> #N/A
B40: PAN BOLLERIA | C40: 39707 | D40: Pan Integral 1p 570g Bolsa LAL | M40: 17.91 | N40: 100 | O40: 0 | P40: 0 | Q40: 17.91 | R40: 100 | S40: 15 | T40: 83.752 | U40: 0 | W40: 17.91 | X40: 100 | AA40: =IFERROR(IF(AC40=1,(I40*AC40),(I40*AC40)),0) -> 0 | AB40: =_xlfn.XLOOKUP($C:$C,'DT PPM'!$F:$F,'DT PPM'!$D:$D) -> #N/A | AC40: =VLOOKUP(C40,'DT PPM'!$C$3:$E$1048576,3,0) -> #N/A
...

Sheet PT (FORMULA)
M1: 1. BAJAS NO RECUPERABLES 2. BAJAS PARA REPROCESO 3. SEGUNDA SELECCIÓN 15.BAJAS PARA DONATIVOS | O1: 4.RESIDUOS/BARREDURA 5.MATERIAS PRIMAS 6.PRUEBAS 7.ARRANQUE NUEVAS LINEAS 8. DESPERDICIO DE DISEÑO NO RECUPERABLE 9.RESIDUOS/BARREDURA PARA REPROCESO 10.PRUEBAS PARA REPROCESO 13.DONATIVOS | Q1: BAJAS + RESIDUOS (*NO SE CONSIDERA EL DESPERDICIO DE DISEÑO PARA REPROCESO) | S1: 2. BAJAS PARA REPROCESO 9.RESIDUOS/BARREDURA PARA REPROCESO 10.PRUEBAS PARA REPROCESO | U1: 1. BAJAS NO RECUPERABLES 4.RESIDUOS/BARREDURA 5.MATERIAS PRIMAS 6.PRUEBAS 8. DESPERDICIO DE DISEÑO NO RECUPERABLE | W1: 2. BAJAS PARA REPROCESO 3. SEGUNDA SELECCIÓN 9.RESIDUOS/BARREDURA PARA REPROCESO 10.PRUEBAS PARA REPROCESO 13.DONATIVOS 15.BAJAS PARA DONATIVOS
B2: Línea | C2: Código producto | D2: Descripción | E2: Uom | F2: Código Masa | G2: Nombre Masa | H2: Masas Elaboradas (Piezas) | I2: Pt Registrado (Piezas) | J2: PT Registrado (Paquetes) | K2: Peso paq (kg) | L2: Toneladas producidas (ton) | M2: Bajas / Desperdicio de Proceso (kg) | N2: % Bajas / Desperdicio de Proceso (BAJAS) | O2: Residuos (kg) | P2: % Residuos (BARREDURA) | Q2: Desperdicio Total (kg) | R2: % Desperdicio Total (TOTAL WASTE) | S2: Reproceso (kg) | T2: % Reproceso | U2: Desperdicio alimento (kg) | V2: % Desperdicio alimento (FOOD WASTE) | W2: Recuperación (kg) | X2: % Recuperación | AA2: PPM | AB2: Cupo Por Bandeja / Caja Primario | AC2: Piezas x Caja
B3: =PT!B3 -> PAN BOLLERIA | C3: =PT!C3 -> 987 | D3: =PT!D3 -> Pan Super Perro 1p 405g Bolsa BIM | E3: =PT!E3 -> 0 | F3: =PT!F3 -> S944 | G3: =PT!G3 -> MASA PAN SUPER PANCHO / PERRO | H3: =PT!H3 -> 29607 | I3: =PT!I3 -> 11124 | ... M3: =PT!M3 -> 39 | N3: =IFERROR((M3/((L3*1000)+Q3))*100,0) -> 4.7446987 | O3: =PT!O3 -> 8 | P3: =IFERROR(+((O3/((L3*1000)+Q3))*100),0) -> 0.97327153 | Q3: =PT!Q3 -> 47 | R3: =IFERROR((Q3/((L3*1000)+Q3))*100,0) -> 5.7179702 | S3: =PT!S3 -> 18 | T3: =IFERROR(((S3)/((L3*1000)+Q3))*100,0) -> 2.1898609 | U3: =PT!U3 -> 29 | V3: =IFERROR(((U3)/((L3*1000)+U3))*100,0) -> 3.6070998 | W3: =PT!W3 -> 18 | X3: =IFERROR(((W3)/((L3*1000)+Q3))*100,0) -> 2.1898609 | AA3: =IFERROR(IF(AC3=1,(I3*AC3),(I3*AC3)),0) -> 0 | AB3: =IFERROR(_xlfn.XLOOKUP($C:$C,'DT PPM'!$F:$F,'DT PPM'!$D:$D),0) -> 0 | AC3: =IFERROR(VLOOKUP(C3,'DT PPM'!$C$3:$E$1048576,3,0),0) -> 0
B4: =PT!B4 -> PAN BOLLERIA | C4: =PT!C4 -> 23618 | D4: =PT!D4 -> Pan Integral 1p 650g Bolsa BIM | E4: =PT!E4 -> EACH | F4: =PT!F4 -> S947 | G4: =PT!G4 -> MASA PAN INTEGRAL 650G BIM | H4: =PT!H4 -> 1565.80* | I4: =PT!I4 -> 4392 | ... M4: =PT!M4 -> 13 | N4: =IFERROR((M4/((L4*1000)+Q4))*100,0) -> 0.44207162 | O4: =PT!O4 -> 0 | P4: =IFERROR(+((O4/((L4*1000)+Q4))*100),0) -> 0 | Q4: =PT!Q4 -> 13 | R4: =IFERROR((Q4/((L4*1000)+Q4))*100,0) -> 0.44207162 | S4: =PT!S4 -> 13 | T4: =IFERROR(((S4)/((L4*1000)+Q4))*100,0) -> 0.44207162 | U4: =PT!U4 -> 0 | V4: =IFERROR(((U4)/((L4*1000)+U4))*100,0) -> 0 | W4: =PT!W4 -> 13 | X4: =IFERROR(((W4)/((L4*1000)+Q4))*100,0) -> 0.44207162 | AA4: =IFERROR(IF(AC4=1,(I4*AC4),(I4*AC4)),0) -> 0 | AB4: =IFERROR(_xlfn.XLOOKUP($C:$C,'DT PPM'!$F:$F,'DT PPM'!$D:$D),0) -> 0 | AC4: =IFERROR(VLOOKUP(C4,'DT PPM'!$C$3:$E$1048576,3,0),0) -> 0
B5: =PT!B5 -> PAN BOLLERIA | C5: =PT!C5 -> 23901 | D5: =PT!D5 -> Pan Vital Fruticereal 1p 500g Bolsa BIM | E5: =PT!E5 -> 0 | F5: =PT!F5 -> S1541 | G5: =PT!G5 -> MASA PAN 100% FRUTICEREAL | H5: =PT!H5 -> 2450.2 | I5: =PT!I5 -> 2717 | ... M5: =PT!M5 -> 24 | N5: =IFERROR((M5/((L5*1000)+Q5))*100,0) -> 1.5524937 | O5: =PT!O5 -> 114.5 | P5: =IFERROR(+((O5/((L5*1000)+Q5))*100),0) -> 7.4066887 | Q5: =PT!Q5 -> 138.5 | R5: =IFERROR((Q5/((L5*1000)+Q5))*100,0) -> 8.9591824 | S5: =PT!S5 -> 0 | T5: =IFERROR(((S5)/((L5*1000)+Q5))*100,0) -> 0 | U5: =PT!U5 -> 138.5 | V5: =IFERROR(((U5)/((L5*1000)+U5))*100,0) -> 8.9591824 | W5: =PT!W5 -> 0 | X5: =IFERROR(((W5)/((L5*1000)+Q5))*100,0) -> 0 | AA5: =IFERROR(IF(AC5=1,(I5*AC5),(I5*AC5)),0) -> 0 | AB5: =IFERROR(_xlfn.XLOOKUP($C:$C,'DT PPM'!$F:$F,'DT PPM'!$D:$D),0) -> 0 | AC5: =IFERROR(VLOOKUP(C5,'DT PPM'!$C$3:$E$1048576,3,0),0) -> 0
B6: =PT!B6 -> PAN BOLLERIA | C6: =PT!C6 -> 26405 | D6: =PT!D6 -> Duopack Pan Integral 1p 1300g Bolsa BIM | E6: =PT!E6 -> 0 | F6: =PT!F6 -> 0 | G6: =PT!G6 -> 0 | H6: =PT!H6 -> 0 | I6: =PT!I6 -> 120 | ... M6: =PT!M6 -> 0 | N6: =IFERROR((M6/((L6*1000)+Q6))*100,0) -> 0 | O6: =PT!O6 -> 0 | P6: =IFERROR(+((O6/((L6*1000)+Q6))*100),0) -> 0 | Q6: =PT!Q6 -> 0 | R6: =IFERROR((Q6/((L6*1000)+Q6))*100,0) -> 0 | S6: =PT!S6 -> 0 | T6: =IFERROR(((S6)/((L6*1000)+Q6))*100,0) -> 0 | U6: =PT!U6 -> 0 | V6: =IFERROR(((U6)/((L6*1000)+U6))*100,0) -> 0 | W6: =PT!W6 -> 0 | X6: =IFERROR(((W6)/((L6*1000)+Q6))*100,0) -> 0 | AA6: =IFERROR(IF(AC6=1,(I6*AC6),(I6*AC6)),0) -> 0 | AB6: =IFERROR(_xlfn.XLOOKUP($C:$C,'DT PPM'!$F:$F,'DT PPM'!$D:$D),0) -> 0 | AC6: =IFERROR(VLOOKUP(C6,'DT PPM'!$C$3:$E$1048576,3,0),0) -> 0
B7: =PT!B7 -> PAN BOLLERIA | C7: =PT!C7 -> 26474 | D7: =PT!D7 -> Pan Leche 1p 550g Bolsa LAL | E7: =PT!E7 -> 0 | F7: =PT!F7 -> S1550 | G7: =PT!G7 -> MASA PAN BLANCO 550G | H7: =PT!H7 -> 7060.80* | I7: =PT!I7 -> 2093 | ... M7: =PT!M7 -> 43.56 | N7: =IFERROR((M7/((L7*1000)+Q7))*100,0) -> 3.3825916 | O7: =PT!O7 -> 51 | P7: =IFERROR(+((O7/((L7*1000)+Q7))*100),0) -> 3.9603345 | Q7: =PT!Q7 -> 94.56 | R7: =IFERROR((Q7/((L7*1000)+Q7))*100,0) -> 7.3429261 | S7: =PT!S7 -> 90 | T7: =IFERROR(((S7)/((L7*1000)+Q7))*100,0) -> 6.9888256 | U7: =PT!U7 -> 0 | V7: =IFERROR(((U7)/((L7*1000)+U7))*100,0) -> 0 | W7: =PT!W7 -> 94.56 | X7: =IFERROR(((W7)/((L7*1000)+Q7))*100,0) -> 7.3429261 | AA7: =IFERROR(IF(AC7=1,(I7*AC7),(I7*AC7)),0) -> 0 | AB7: =IFERROR(_xlfn.XLOOKUP($C:$C,'DT PPM'!$F:$F,'DT PPM'!$D:$D),0) -> 0 | AC7: =IFERROR(VLOOKUP(C7,'DT PPM'!$C$3:$E$1048576,3,0),0) -> 0
B8: =PT!B8 -> PAN BOLLERIA | C8: =PT!C8 -> 26475 | D8: =PT!D8 -> Pan Mantequilla 1p 550g Bolsa LAL | E8: =PT!E8 -> 0 | F8: =PT!F8 -> S1552 | G8: =PT!G8 -> MASA PAN MATEQUILLA 550G | H8: =PT!H8 -> 8788.00* | I8: =PT!I8 -> 4417 | ... M8: =PT!M8 -> 63.93 | N8: =IFERROR((M8/((L8*1000)+Q8))*100,0) -> 2.3642227 | O8: =PT!O8 -> 122 | P8: =IFERROR(+((O8/((L8*1000)+Q8))*100),0) -> 4.5117342 | Q8: =PT!Q8 -> 185.93 | R8: =IFERROR((Q8/((L8*1000)+Q8))*100,0) -> 6.8759569 | S8: =PT!S8 -> 125 | T8: =IFERROR(((S8)/((L8*1000)+Q8))*100,0) -> 4.6226785 | U8: =PT!U8 -> 33 | V8: =IFERROR(((U8)/((L8*1000)+U8))*100,0) -> 1.2935444 | W8: =PT!W8 -> 152.93 | X8: =IFERROR(((W8)/((L8*1000)+Q8))*100,0) -> 5.6555698 | AA8: =IFERROR(IF(AC8=1,(I8*AC8),(I8*AC8)),0) -> 0 | AB8: =IFERROR(_xlfn.XLOOKUP($C:$C,'DT PPM'!$F:$F,'DT PPM'!$D:$D),0) -> 0 | AC8: =IFERROR(VLOOKUP(C8,'DT PPM'!$C$3:$E$1048576,3,0),0) -> 0
B9: =PT!B9 -> PAN BOLLERIA | C9: =PT!C9 -> 27031 | D9: =PT!D9 -> Dpack Pan Fruticereal 1p 1000g Bolsa BIM | E9: =PT!E9 -> 0 | F9: =PT!F9 -> 0 | G9: =PT!G9 -> 0 | H9: =PT!H9 -> 0 | I9: =PT!I9 -> 260 | ... M9: =PT!M9 -> 0 | N9: =IFERROR((M9/((L9*1000)+Q9))*100,0) -> 0 | O9: =PT!O9 -> 0 | P9: =IFERROR(+((O9/((L9*1000)+Q9))*100),0) -> 0 | Q9: =PT!Q9 -> 0 | R9: =IFERROR((Q9/((L9*1000)+Q9))*100,0) -> 0 | S9: =PT!S9 -> 0 | T9: =IFERROR(((S9)/((L9*1000)+Q9))*100,0) -> 0 | U9: =PT!U9 -> 0 | V9: =IFERROR(((U9)/((L9*1000)+U9))*100,0) -> 0 | W9: =PT!W9 -> 0 | X9: =IFERROR(((W9)/((L9*1000)+Q9))*100,0) -> 0 | AA9: =IFERROR(IF(AC9=1,(I9*AC9),(I9*AC9)),0) -> 0 | AB9: =IFERROR(_xlfn.XLOOKUP($C:$C,'DT PPM'!$F:$F,'DT PPM'!$D:$D),0) -> 0 | AC9: =IFERROR(VLOOKUP(C9,'DT PPM'!$C$3:$E$1048576,3,0),0) -> 0
B10: =PT!B10 -> PAN BOLLERIA | C10: =PT!C10 -> 28632 | D10: =PT!D10 -> Pan Mantequilla 1p 600g Bolsa BIM | E10: =PT!E10 -> 0 | F10: =PT!F10 -> S1557 | G10: =PT!G10 -> MASA PAN MANTEQUILLA 600G | H10: =PT!H10 -> 823.5 | I10: =PT!I10 -> 3448 | ... M10: =PT!M10 -> 21 | N10: =IFERROR((M10/((L10*1000)+Q10))*100,0) -> 0.97589992 | O10: =PT!O10 -> 0 | P10: =IFERROR(+((O10/((L10*1000)+Q10))*100),0) -> 0 | Q10: =PT!Q10 -> 21 | R10: =IFERROR((Q10/((L10*1000)+Q10))*100,0) -> 0.97589992 | S10: =PT!S10 -> 21 | T10: =IFERROR(((S10)/((L10*1000)+Q10))*100,0) -> 0.97589992 | U10: =PT!U10 -> 0 | V10: =IFERROR(((U10)/((L10*1000)+U10))*100,0) -> 0 | W10: =PT!W10 -> 21 | X10: =IFERROR(((W10)/((L10*1000)+Q10))*100,0) -> 0.97589992 | AA10: =IFERROR(IF(AC10=1,(I10*AC10),(I10*AC10)),0) -> 0 | AB10: =IFERROR(_xlfn.XLOOKUP($C:$C,'DT PPM'!$F:$F,'DT PPM'!$D:$D),0) -> 0 | AC10: =IFERROR(VLOOKUP(C10,'DT PPM'!$C$3:$E$1048576,3,0),0) -> 0
B11: =PT!B11 -> PAN BOLLERIA | C11: =PT!C11 -> 29076 | D11: =PT!D11 -> Pan Super Perro 12p 4860g CJA BIM | E11: =PT!E11 -> 0 | F11: =PT!F11 -> S944 | G11: =PT!G11 -> MASA PAN SUPER PANCHO / PERRO | H11: =PT!H11 -> 29607 | I11: =PT!I11 -> 10080 | ... M11: =PT!M11 -> 0 | N11: =IFERROR((M11/((L11*1000)+Q11))*100,0) -> 0 | O11: =PT!O11 -> 0 | P11: =IFERROR(+((O11/((L11*1000)+Q11))*100),0) -> 0 | Q11: =PT!Q11 -> 0 | R11: =IFERROR((Q11/((L11*1000)+Q11))*100,0) -> 0 | S11: =PT!S11 -> 0 | T11: =IFERROR(((S11)/((L11*1000)+Q11))*100,0) -> 0 | U11: =PT!U11 -> 0 | V11: =IFERROR(((U11)/((L11*1000)+U11))*100,0) -> 0 | W11: =PT!W11 -> 0 | X11: =IFERROR(((W11)/((L11*1000)+Q11))*100,0) -> 0 | AA11: =IFERROR(IF(AC11=1,(I11*AC11),(I11*AC11)),0) -> 0 | AB11: =IFERROR(_xlfn.XLOOKUP($C:$C,'DT PPM'!$F:$F,'DT PPM'!$D:$D),0) -> 0 | AC11: =IFERROR(VLOOKUP(C11,'DT PPM'!$C$3:$E$1048576,3,0),0) -> 0
B12: =PT!B12 -> PAN BOLLERIA | C12: =PT!C12 -> 29434 | D12: =PT!D12 -> Pan Super Hamburguesa 12p 4200g CJA BIM | E12: =PT!E12 -> cg | F12: =PT!F12 -> S1088 | G12: =PT!G12 -> MASA HAMBURGUESA 5" -2- | H12: =PT!H12 -> 3570.04 | I12: =PT!I12 -> 11760 | ... M12: =PT!M12 -> 0 | N12: =IFERROR((M12/((L12*1000)+Q12))*100,0) -> 0 | O12: =PT!O12 -> 0 | P12: =IFERROR(+((O12/((L12*1000)+Q12))*100),0) -> 0 | Q12: =PT!Q12 -> 0 | R12: =IFERROR((Q12/((L12*1000)+Q12))*100,0) -> 0 | S12: =PT!S12 -> 0 | T12: =IFERROR(((S12)/((L12*1000)+Q12))*100,0) -> 0 | U12: =PT!U12 -> 0 | V12: =IFERROR(((U12)/((L12*1000)+U12))*100,0) -> 0 | W12: =PT!W12 -> 0 | X12: =IFERROR(((W12)/((L12*1000)+Q12))*100,0) -> 0 | AA12: =IFERROR(IF(AC12=1,(I12*AC12),(I12*AC12)),0) -> 0 | AB12: =IFERROR(_xlfn.XLOOKUP($C:$C,'DT PPM'!$F:$F,'DT PPM'!$D:$D),0) -> 0 | AC12: =IFERROR(VLOOKUP(C12,'DT PPM'!$C$3:$E$1048576,3,0),0) -> 0
B13: =PT!B13 -> PAN BOLLERIA | C13: =PT!C13 -> 41647 | D13: =PT!D13 -> Pan Mantequilla 12p 6600g CJA LAL | E13: =PT!E13 -> cg | F13: =PT!F13 -> S1552 | G13: =PT!G13 -> MASA PAN MATEQUILLA 550G | H13: =PT!H13 -> 8788 | I13: =PT!I13 -> 10080 | ... M13: =PT!M13 -> 0 | N13: =IFERROR((M13/((L13*1000)+Q13))*100,0) -> 0 | O13: =PT!O13 -> 0 | P13: =IFERROR(+((O13/((L13*1000)+Q13))*100),0) -> 0 | Q13: =PT!Q13 -> 0 | R13: =IFERROR((Q13/((L13*1000)+Q13))*100,0) -> 0 | S13: =PT!S13 -> 0 | T13: =IFERROR(((S13)/((L13*1000)+Q13))*100,0) -> 0 | U13: =PT!U13 -> 0 | V13: =IFERROR(((U13)/((L13*1000)+U13))*100,0) -> 0 | W13: =PT!W13 -> 0 | X13: =IFERROR(((W13)/((L13*1000)+Q13))*100,0) -> 0 | AA13: =IFERROR(IF(AC13=1,(I13*AC13),(I13*AC13)),0) -> 0 | AB13: =IFERROR(_xlfn.XLOOKUP($C:$C,'DT PPM'!$F:$F,'DT PPM'!$D:$D),0) -> 0 | AC13: =IFERROR(VLOOKUP(C13,'DT PPM'!$C$3:$E$1048576,3,0),0) -> 0
B14: =PT!B14 -> PAN BOLLERIA | C14: =PT!C14 -> 41648 | D14: =PT!D14 -> Pan Leche 12p 6600g CJA LAL | E14: =PT!E14 -> cg | F14: =PT!F14 -> S1550 | G14: =PT!G14 -> MASA PAN BLANCO 550G | H14: =PT!H14 -> 7060.8 | I14: =PT!I14 -> 7980 | ... M14: =PT!M14 -> 0 | N14: =IFERROR((M14/((L14*1000)+Q14))*100,0) -> 0 | O14: =PT!O14 -> 0 | P14: =IFERROR(+((O14/((L14*1000)+Q14))*100),0) -> 0 | Q14: =PT!Q14 -> 0 | R14: =IFERROR((Q14/((L14*1000)+Q14))*100,0) -> 0 | S14: =PT!S14 -> 0 | T14: =IFERROR(((S14)/((L14*1000)+Q14))*100,0) -> 0 | U14: =PT!U14 -> 0 | V14: =IFERROR(((U14)/((L14*1000)+U14))*100,0) -> 0 | W14: =PT!W14 -> 0 | X14: =IFERROR(((W14)/((L14*1000)+Q14))*100,0) -> 0 | AA14: =IFERROR(IF(AC14=1,(I14*AC14),(I14*AC14)),0) -> 0 | AB14: =IFERROR(_xlfn.XLOOKUP($C:$C,'DT PPM'!$F:$F,'DT PPM'!$D:$D),0) -> 0 | AC14: =IFERROR(VLOOKUP(C14,'DT PPM'!$C$3:$E$1048576,3,0),0) -> 0
... B59: =PT!B59 -> PLANTA | C59: =PT!C59 -> Total | D59: =PT!D59 -> 0 | E59: =PT!E59 -> 0 | F59: =PT!F59 -> 0 | G59: =PT!G59 -> 0 | H59: =PT!H59 -> 827338.19 | I59: =PT!I59 -> 767156 | ... M59: =PT!M59 -> 863.28 | N59: =IFERROR((M59/((L59*1000)+Q59))*100,0) -> 0.80986161 | O59: =PT!O59 -> 603.5 | P59: =IFERROR(+((O59/((L59*1000)+Q59))*100),0) -> 0.56615638 | Q59: =PT!Q59 -> 1466.78 | R59: =IFERROR((Q59/((L59*1000)+Q59))*100,0) -> 1.376018 | S59: =PT!S59 -> 708.5 | T59: =IFERROR(((S59)/((L59*1000)+Q59))*100,0) -> 0.66465915 | U59: =PT!U59 -> 664.5 | V59: =IFERROR(((U59)/((L59*1000)+U59))*100,0) -> 0.62810918 | W59: =PT!W59 -> 802.28 | X59: =IFERROR(((W59)/((L59*1000)+Q59))*100,0) -> 0.75263619 | AA59: =IFERROR(IF(AC59=1,(I59*AC59),(I59*AC59)),0) -> 0 | AB59: =IFERROR(_xlfn.XLOOKUP($C:$C,'DT PPM'!$F:$F,'DT PPM'!$D:$D),0) -> 0 | AC59: =IFERROR(VLOOKUP(C59,'DT PPM'!$C$3:$E$1048576,3,0),0) -> 0
X61: =W59/Q59 -> 0.54696683
H62: =H59-PT!H59 -> 0 | I62: =I59-PT!I59 -> 0 | J62: =J59-PT!J59 -> 0 | L62: =L59-PT!L59 -> 0 | M62: =M59-PT!M59 -> 0 | N62: =N59-PT!N59 -> 6.1609241e-05 | O62: =O59-PT!O59 -> 0 | P62: =P59-PT!P59 -> 5.638168e-05 | Q62: =Q59-PT!Q59 -> 0 | R62: =R59-PT!R59 -> 1.7990921e-05 | S62: =S59-PT!S59 -> 0 | ... Z62: =Z59-PT!Z59 -> 0

Sheet DT PPM
B2: Línea | C2: Código producto | D2: Cupo Por Bandeja / Caja Primario | E2: Piezas x Caja
B3: PAN BOLLERIA | C3: 0987 | D3: 9 | E3: 1 | F3: 0987
B4: PAN BOLLERIA | C4: 23618 | D4: 8 | E4: 1 | F4: 23618
B5: PAN BOLLERIA | C5: 23901 | D5: 13 | E5: 1 | F5: 23901
B6: PAN BOLLERIA | C6: 23935 | D6: 4 | E6: 2 | F6: 23935
B7: PAN BOLLERIA | C7: 26405 | D7: 3 | E7: 1 | F7: 26405
B8: PAN BOLLERIA | C8: 26474 | D8: 7 | E8: 1 | F8: 26474
B9: PAN BOLLERIA | C9: 26475 | D9: 7 | E9: 1 | F9: 26475
B10: PAN BOLLERIA | C10: 27031 | D10: 5 | E10: 1 | F10: 27031
B11: PAN BOLLERIA | C11: 28632 | D11: 8 | E11: 1 | F11: 28632
B12: PAN BOLLERIA | C12: 29076 | D12: 1 | E12: 12 | F12: 29076
B13: PAN BOLLERIA | C13: 29434 | D13: 1 | E13: 12 | F13: 29434
B14: PAN BOLLERIA | C14: 29580 | D14: 9 | E14: 1 | F14: 29580
... B39: PAN BOLLERIA | C39: 39707 | D39: 7 | E39: 1 | F39: 39707
B40: PAN BOLLERIA | C40: 963603 | D40: 4 | E40: 2 | F40: =+C40 -> 963603
B41: PAN BOLLERIA | C41: Total | D41: 0 | E41: 0 | F41: Total
B42: TORTILLAS | C42: 1649 | D42: 24 | E42: 1 | F42: 1649
B43: TORTILLAS | C43: 26504 | D43: 4 | E43: 1 | F43: 26504
B44: TORTILLAS | C44: 29073 | D44: 12 | E44: 1 | F44: 29073
B45: TORTILLAS | C45: 29074 | D45: 24 | E45: 1 | F45: 29074
B46: TORTILLAS | C46: 49271 | D46: 1 | E46: 18 | F46: 49271
B47: TORTILLAS | C47: 500498 | D47: 24 | E47: 1 | F47: 500498
B48: TORTILLAS | C48: 5490 | D48: 24 | E48: 1 | F48: 5490
B49: TORTILLAS | C49: 6026 | D49: 9 | E49: 1 | F49: 6026
B50: TORTILLAS | C50: 8063 | D50: 4 | E50: 1 | F50: 8063
B51: TORTILLAS | C51: 8062 | D51: 8 | E51: 1 | F51: 8062
B52: TORTILLAS | C52: Total | D52: 0 | E52: 0 | F52: Total
... B55: PLANTA | C55: Total | D55: 0 | E55: 0 | F55: Total

Sheet RESUMEN
E4: KPI | F4: % Bajas (Desperdicios Operativos) | G4: % Barredura | H4: % Total waste | I4: % Food waste | J4: Recup. | K4: % IPFM | L4: OEE1 | M4: OEE2 | N4: Efect | O4: Rend. | P4: Fill Rate 1 | Q4: % CU
B5: FECHA | E5: META% | F5: 0.0106 | G5: 0.0082 | H5: 0.0189 | I5: 0.013 | J5: 0.38 | K5: 0.017 | L5: 32.6 | M5: 0.92 | N5: 0.86 | O5: 0.975 | P5: 0.95 | Q5: 0.5
B6: INICIO | C6: FINAL | E6: META% | F6: =F5*100 -> 1.06 | G6: =G5*100 -> 0.82 | H6: =H5*100 -> 1.89 | I6: =I5*100 -> 1.3 | J6: =J5 -> 0.38 | K6: =K5*100 -> 1.7 | L6: =L5 -> 32.6 | M6: =M5*100 -> 92 | N6: =N5*100 -> 86 | O6: =O5*100 -> 97.5 | P6: =P5*100 -> 95 | Q6: =Q5*100 -> 50
A7: Diario | E7: META PAN BOLLERIA | F7: 1 | G7: 0.8 | H7: 1.7 | I7: 0.9 | J7: 0.38 | K7: 2 | L7: 20.86 | M7: 84 | N7: 89 | O7: 96 | P7: 95 | Q7: 50
E8: META PANQUELERIA | F8: 1.06 | G8: 0.9 | H8: 1.89 | I8: 1.3 | J8: 0.38 | K8: 1.7 | L8: 32.6 | M8: 84 | N8: 86 | O8: 97.5 | P8: 95 | Q8: 50
E9: META TORTILLAS | F9: 0.46 | G9: 0.44 | H9: 0.9 | I9: 0.7 | J9: 0.4 | K9: 1.37 | L9: 39.09 | M9: 92 | N9: 95 | O9: 99.5 | P9: 95 | Q9: 50
E10: RESULTADO GBC | F10: =PT!N59 -> 0.8098 | G10: =PT!P59 -> 0.5661 | H10: =PT!R59 -> 1.376 | I10: =PT!V59 -> 0.6281 | J10: =PT!X61 -> 0.54696683 | K10: ='OEE2'!Y6 -> 0.3083651 | L10: ='OEE2'!U6 -> 33.19 | M10: ='OEE2'!V6 -> 93.78 | N10: ='OEE2'!S6 -> 96.53 | O10: ='OEE2'!T6 -> 97.15 | P10: 97.94 | Q10: ='OEE2'!R6 -> 35.38
E11: RESULTADO MANUAL | F11: ='PT (FORMULA)'!N59 -> 0.80986161 | G11: ='PT (FORMULA)'!P59 -> 0.56615638 | H11: ='PT (FORMULA)'!R59 -> 1.376018 | I11: ='PT (FORMULA)'!V59 -> 0.62810918 | J11: ='PT (FORMULA)'!X61 -> 0.54696683 | K11: ='OEE2 (FORMULA)'!Y6 -> 0.30834782 | L11: ='OEE2 (FORMULA)'!U6 -> 33.192652 | M11: ='OEE2 (FORMULA)'!V6 -> 93.788735 | N11: ='OEE2 (FORMULA)'!S6 -> 96.535292 | O11: ='OEE2 (FORMULA)'!T6 -> 97.154867 | P11: =+P10 -> 97.94 | Q11: ='OEE2 (FORMULA)'!R6 -> 35.390873
A12: Acumulado | E12: GBC
A13: Sem 1 | B13: 46022 | C13: 46028 | E13: GBC | F13: 0.47 | G13: 0 | H13: 0.47 | I13: 0.11 | J13: 0.7647 | K13: 0.43 | L13: 24.19 | M13: 94.79 | N13: 97 | O13: 97.71 | Q13: 25.52
A14: Sem 1 | B14: 46022 | C14: 46028 | E14: MANUAL | F14: 1.27 | G14: 0.49 | H14: 1.76 | I14: 0.73 | J14: 0.5171 | K14: 0.55 | L14: 21.81 | M14: 92.97 | N14: 96.24 | O14: 96.6 | P14: 97.85 | Q14: 23.46
A15: Sem 2 | B15: 46029 | C15: 46035 | E15: GBC | F15: 1.329 | G15: 0.89 | H15: 2.21 | I15: 1.43 | J15: 0.3604 | K15: 1.13 | L15: 24.34 | M15: 78.27 | N15: 81.55 | O15: 95.97 | Q15: 31.1
A16: Sem 2 | B16: 46029 | C16: 46035 | E16: MANUAL | F16: 1.33 | G16: 0.89 | H16: 3.24 | I16: 1.43 | J16: 0.3604 | K16: 1.26 | L16: 25.14 | M16: 89.96 | N16: 93.74 | O16: 95.97 | P16: 95.22 | Q16: 27.94
A17: Sem 3 | B17: 46036 | C17: 46042 | E17: GBC | F17: 1.08 | G17: 1.1 | H17: 2.18 | I17: 1.41 | J17: 0.3581 | K17: 1.516 | L17: 34.64 | M17: 90.06 | N17: 93.96 | O17: 95.84 | Q17: 38.46
A18: Sem 3 | B18: 46036 | C18: 46042 | E18: MANUAL | F18: 1.08 | G18: 1.1 | H18: 2.85 | I18: 1.41 | J18: 0.3582 | K18: 1.52 | L18: 34.95 | M18: 90.85 | N18: 93.96 | O18: 96.69 | P18: 89.9 | Q18: 38.46
A19: Sem 4 | B19: 46043 | C19: 46049 | E19: GBC | F19: 1.06 | G19: 0.408 | H19: 1.47 | I19: 1.205 | J19: 0.1834 | K19: 2.185 | L19: 35.99 | M19: 95.07 | N19: 93.28 | O19: 101.92 | Q19: 37.86
A20: Sem 4 | B20: 46043 | C20: 46049 | E20: MANUAL | F20: 1.06 | G20: 0.41 | H20: 3.09 | I20: 1.21 | J20: 0.1835 | K20: 2.19 | L20: 35.99 | M20: 95.07 | N20: 93.28 | O20: 101.92 | P20: 97.4 | Q20: 37.86
A21: Sem 5 | B21: 46050 | C21: 46056 | E21: GBC | F21: 0.83 | G21: 0.56 | H21: 1.39 | I21: 0.58 | J21: 0.5834 | K21: 0.615 | L21: 34.64 | M21: 88.02 | N21: 88.8 | O21: 99.12 | Q21: 39.35
A22: Sem 5 | B22: 46050 | C22: 46056 | E22: MANUAL | F22: 0.83 | G22: 0.56 | H22: 1.39 | I22: 0.58 | J22: 0.5834 | K22: 0.66 | L22: 35.3 | M22: 96.63 | N22: 97.49 | O22: 99.12 | P22: 98.67 | Q22: 36.53
A23: Sem 6 | B23: 46057 | C23: 46063 | E23: GBC | F23: 0.77 | G23: 0.62 | H23: 1.39 | I23: 0.5 | J23: 0.6434 | K23: 0.39 | L23: 37.57 | M23: 93.7 | N23: 95.22 | O23: 98.4 | Q23: 40.09
A24: Sem 6 | B24: 46057 | C24: 46063 | E24: MANUAL | F24: 0.77 | G24: 0.62 | H24: 1.39 | I24: 0.5 | J24: 0.6434 | K24: 0.39 | L24: 37.9 | M24: 94.53 | N24: 96.07 | O24: 98.4 | P24: 98.81 | Q24: 40.09
A25: Sem 7 | B25: 46064 | C25: 46070 | E25: GBC | F25: 0.81 | G25: 0.58 | H25: 1.4 | I25: 0.41 | J25: 0.7091 | K25: 0.09 | L25: 35.02 | M25: 92.7 | N25: 94.62 | O25: 97.96 | Q25: 37.77
A26: Sem 7 | B26: 46064 | C26: 46070 | E26: MANUAL | F26: 0.81 | G26: 0.58 | H26: 1.4 | I26: 0.41 | J26: 0.7091 | K26: 0.09 | L26: 35.02 | M26: 92.7 | N26: 94.62 | O26: 97.96 | P26: 98.61 | Q26: 37.77
A27: Sem 8 | B27: 46071 | C27: 46077 | E27: GBC | F27: 1.4 | G27: 3.3 | H27: 4.709 | I27: 3.94 | J27: 0.1692 | K27: 0.78 | L27: 40.93 | M27: 90.96 | N27: 92.33 | O27: 98.51 | Q27: 44.99
A28: Sem 8 | B28: 46071 | C28: 46077 | E28: MANUAL | F28: 1.4 | G28: 3.31 | H28: 4.71 | I28: 3.94 | J28: 0.1692 | K28: 0.78 | L28: 40.93 | M28: 90.96 | N28: 92.33 | O28: 98.51 | P28: 97.23 | Q28: 44.99
A29: Sem 9 | B29: 46078 | C29: 46084 | E29: GBC | F29: 0.74 | G29: 0.93 | H29: 1.67 | I29: 1.26 | J29: 0.2489 | K29: 0.05 | L29: 33.45 | M29: 93.72 | N29: 95.56 | O29: 93.72 | Q29: 37.34
A30: Sem 9 | B30: 46078 | C30: 46084 | E30: MANUAL | F30: 0.74 | G30: 0.93 | H30: 1.67 | I30: 1.26 | J30: 0.2489 | K30: 0.05 | L30: 33.45 | M30: 89.56 | N30: 95.56 | O30: 93.72 | P30: 94.09 | Q30: 37.34
A31: Sem 10 | B31: 46085 | C31: 46091 | E31: GBC | F31: 0.84 | G31: 0.65 | H31: 1.49 | I31: 0.6 | J31: 0.6041 | K31: 1.29 | L31: 35.16 | M31: 91.44 | N31: 90.14 | O31: 101.44 | Q31: 38.44
A32: Sem 10 | B32: 46085 | C32: 46091 | E32: MANUAL | F32: 0.84 | G32: 0.59 | H32: 1.43 | I32: 0.53 | J32: 0.6307 | K32: 1.34 | L32: 35.16 | M32: 94.7 | N32: 93.35 | O32: 101.44 | P32: 98.89 | Q32: 37.13
A33: Sem 11 | B33: 46092 | C33: 46098 | E33: GBC
A34: Sem 11 | B34: 46092 | C34: 46098 | E34: MANUAL
A35: Sem 12 | B35: 46099 | C35: 46105
A36: Sem 13 | B36: 46106 | C36: 46112
A37: Sem 14 | B37: 46113 | C37: 46119
A38: Sem 15 | B38: 46120 | C38: 46126
A39: Sem 16 | B39: 46127 | C39: 46133
A40: Sem 17 | B40: 46134 | C40: 46140
A41: Sem 18 | B41: 46141 | C41: 46147
A42: Sem 19 | B42: 46148 | C42: 46154
A43: Sem 20 | B43: 46155 | C43: 46161
...

Sheet INFORME EJECUTIVO
A1: INFORME EJECUTIVO DE PRODUCCIÓN
A2: Comparativo vivo de metas, desperdicio, productividad y pérdidas con todos los registros actuales de PT y OEE2 | N2: Fila PT | O2: Línea | P2: Código | Q2: Descripción | R2: Desperdicio kg | S2: Desperdicio % | T2: Producto válido | U2: Ranking
